Workbook

Sheet Hướng dẫn
A1: HƯỚNG DẪN KHAI BÁO TÀI NGUYÊN SỐ KHỐI MKT
A3: Mục đích | B3: Thu thập toàn bộ tài nguyên mỗi ban đang giữ tính đến nay, trước khi Phòng Tài nguyên cấp phát lại theo quy trình mới.
A4: Hạn nộp | B4: (Phòng Tài nguyên điền hạn nộp vào đây)
A5: Bước 1 – Khai người sử dụng | B5: Trưởng ban vào tab "Người sử dụng", khai toàn bộ nhân sự của ban mình (kể cả người đã nghỉ nhưng từng giữ tài nguyên), chọn Ban và Trạng thái.
A6: Bước 2 – Khai tài nguyên | B6: Vào tab của ban mình, mỗi tài nguyên một dòng. Cột "Người được bàn giao (đang quản lý)" chọn tên nhân viên đang quản lý tài sản đó, từ danh sách đã khai ở Bước 1.
A7: Tài nguyên cần khai | B7: Via, Page, Nhóm, tài khoản AI (ChatGPT, Claude, CapCut, Midjourney…), TKQC, BM và tài nguyên khác ban đang dùng. Khai cả tài nguyên tự tạo, mua ngoài hoặc nhận lại từ người cũ.
A8: QUAN TRỌNG | B8: Không ghi mật khẩu vào file. Mật khẩu và mã 2 lớp sẽ bàn giao trực tiếp cho Phòng Tài nguyên.
A9: Màu ô | B9: Xanh nhạt: ban điền · Xám: tự tính, không sửa · Hồng: Phòng Tài nguyên điền (Bàn giao và trạng thái theo tháng).
A10: Cảnh báo đỏ | B10: Ô "Trạng thái người dùng" báo đỏ khi tài nguyên đang nằm ở người đã nghỉ việc hoặc tên chưa có trong danh sách. Ở tab Người sử dụng, cả dòng tô đỏ khi người đã nghỉ/chuyển ban mà vẫn còn giữ tài nguyên.
A11: Tra cứu theo nhân viên | B11: Vào tab Tổng hợp, chọn tên nhân viên ở ô hồng đầu trang: file liệt kê toàn bộ tài sản người đó đang quản lý trên cả 5 ban, kèm số lượng theo loại và trạng thái gần nhất.
A12: Theo dõi theo thời gian | B12: Mỗi tài nguyên giữ nguyên 1 dòng. Mỗi tháng rà soát, Phòng Tài nguyên chọn trạng thái ở cột tháng đó, kéo ngang là thấy lịch sử.
A13: Trạng thái tài nguyên | B13: Hoạt động · Hạn chế (bị giới hạn tính năng) · Checkpoint (khóa tạm, cần xác minh) · Die / Mất (không lấy lại được) · Đã thu hồi · Ngừng dùng
A14: Trạng thái nhân sự | B14: Đang làm · Thử việc · Tạm nghỉ (nghỉ dài ngày, vẫn còn hợp đồng) · Chuyển ban · Đã nghỉ việc
A15: Danh sách lựa chọn | B15: Muốn thêm loại, quyền hoặc trạng thái thì sửa ở tab Danh mục (thêm vào cuối cột, không chèn dòng giữa).
A17: DÒNG MẪU – TAB NGƯỜI SỬ DỤNG (tham khảo, không điền vào đây)
A18: STT | B18: Mã nhân viên | C18: Họ tên | D18: Ban | E18: Chức vụ | F18: SĐT | G18: Email công ty | H18: Trạng thái | I18: Ngày vào làm | J18: Ngày nghỉ / chuyển ban | K18: Số tài nguyên đang giữ | L18: Ghi chú
A19: 1 | B19: NV0123 | C19: Nguyễn Thu Hà | D19: ADS | E19: Nhân viên Ads | F19: 0912xxxxxx | G19: ha.nt@apexmed.vn | H19: Đang làm | I19: 01/03/2025 | K19: (tự tính) | L19: Phụ trách khu vực HN
A21: DÒNG MẪU – TAB CỦA BAN (tham khảo, không điền vào đây)
A22: STT | B22: Mã tài nguyên | C22: Loại tài nguyên | D22: ID tài nguyên | E22: Tên tài nguyên | F22: Link | G22: Người được bàn giao (đang quản lý) | H22: Trạng thái người dùng | I22: Quyền đang có | J22: Email đăng ký | K22: SĐT đăng ký | L22: Bảo mật 2 lớp | M22: Ai đang giữ mã 2 lớp | N22: Nguồn gốc | O22: Ngày bắt đầu dùng | P22: Mục đích sử dụng | Q22: Bàn giao về Tài nguyên | R22: Ghi chú
A23: 1 | B23: ADS-001 | C23: Page | D23: 104857392018475 | E23: Apexmed – Tư vấn chị em | F23: facebook.com/... | G23: Nguyễn Thu Hà | H23: (tự hiện) | I23: Chủ sở hữu / Admin | J23: ads.apexmed@gmail.com | K23: 0912xxxxxx | L23: Có | M23: Nguyễn Thu Hà | N23: Tự tạo | O23: 15/03/2025 | P23: Chạy quảng cáo khu vực HN | Q23: Chưa bàn giao | R23: Page có 2 admin cá nhân

Sheet Tổng hợp
A1: TỔNG HỢP TÀI NGUYÊN KHỐI MKT
A2: Tự động tính từ các tab, không cần sửa. Thống kê theo ban ở phía dưới, từ dòng 113.
A3: 1. TRA CỨU TÀI SẢN THEO NHÂN VIÊN
A4: Chọn nhân viên: | C4: Đỗ Viết Huy
A5: Ban: | B5: {=IF($C$4="","",IFERROR(INDEX('Người sử dụng'!$D$5:$D$140,MATCH($C$4,'Người sử dụng'!$C$5:$C$140,0)),""))} -> Phòng Tài nguyên | E5: Trạng thái: | F5: {=IF($C$4="","",IFERROR(INDEX('Người sử dụng'!$H$5:$H$140,MATCH($C$4,'Người sử dụng'!$C$5:$C$140,0)),""))} -> Đang làm | H5: Tổng tài sản đang giữ: | J5: =IF($C$4="","",MAX('Dữ liệu gộp'!$L$2:$L$1001)) -> #REF!
A6: Theo loại: | B6: Via | C6: Page | D6: Nhóm | E6: AI | F6: TKQC | G6: BM | H6: Khác
B7: =IF($C$4="","",COUNTIFS('Dữ liệu gộp'!$G$2:$G$1001,$C$4,'Dữ liệu gộp'!$C$2:$C$1001,"Via")) -> 1 | C7: =IF($C$4="","",COUNTIFS('Dữ liệu gộp'!$G$2:$G$1001,$C$4,'Dữ liệu gộp'!$C$2:$C$1001,"Page")) -> 0 | D7: =IF($C$4="","",COUNTIFS('Dữ liệu gộp'!$G$2:$G$1001,$C$4,'Dữ liệu gộp'!$C$2:$C$1001,"Nhóm")) -> 0 | E7: =IF($C$4="","",COUNTIFS('Dữ liệu gộp'!$G$2:$G$1001,$C$4,'Dữ liệu gộp'!$C$2:$C$1001,"AI")) -> 0 | F7: =IF($C$4="","",COUNTIFS('Dữ liệu gộp'!$G$2:$G$1001,$C$4,'Dữ liệu gộp'!$C$2:$C$1001,"TKQC")) -> 0 | G7: =IF($C$4="","",COUNTIFS('Dữ liệu gộp'!$G$2:$G$1001,$C$4,'Dữ liệu gộp'!$C$2:$C$1001,"BM")) -> 0 | H7: =IF($C$4="","",COUNTIFS('Dữ liệu gộp'!$G$2:$G$1001,$C$4,'Dữ liệu gộp'!$C$2:$C$1001,"Khác")) -> 0
A9: STT | B9: Ban | C9: Mã tài nguyên | D9: Loại | E9: ID tài nguyên | F9: Tên tài nguyên | G9: Link | H9: Quyền đang có | I9: Bảo mật 2 lớp | J9: Bàn giao về Tài nguyên | K9: Trạng thái gần nhất
A10: =IF(Z10="","",1) -> 1 | B10: {=IF($Z10="","",INDEX('Dữ liệu gộp'!$A$2:$A$1001,$Z10))} -> ADS | C10: {=IF($Z10="","",INDEX('Dữ liệu gộp'!$B$2:$B$1001,$Z10))} -> ADS-001 | D10: {=IF($Z10="","",INDEX('Dữ liệu gộp'!$C$2:$C$1001,$Z10))} -> Via | E10: {=IF($Z10="","",INDEX('Dữ liệu gộp'!$D$2:$D$1001,$Z10))} -> 12356489755 | F10: {=IF($Z10="","",INDEX('Dữ liệu gộp'!$E$2:$E$1001,$Z10))} -> Via Ads 1 | G10: {=IF($Z10="","",INDEX('Dữ liệu gộp'!$F$2:$F$1001,$Z10))} -> abcxyz.com | H10: {=IF($Z10="","",INDEX('Dữ liệu gộp'!$H$2:$H$1001,$Z10))} -> Chủ sở hữu / Admin | I10: {=IF($Z10="","",INDEX('Dữ liệu gộp'!$I$2:$I$1001,$Z10))} | J10: {=IF($Z10="","",INDEX('Dữ liệu gộp'!$J$2:$J$1001,$Z10))} -> Đã bàn giao | K10: {=IF($Z10="","",INDEX('Dữ liệu gộp'!$K$2:$K$1001,$Z10))} | Z10: =IF($C$4="","",IFERROR(MATCH(1,'Dữ liệu gộp'!$L$2:$L$1001,0),"")) -> 1
A11: =IF(Z11="","",2) | B11: {=IF($Z11="","",INDEX('Dữ liệu gộp'!$A$2:$A$1001,$Z11))} | C11: {=IF($Z11="","",INDEX('Dữ liệu gộp'!$B$2:$B$1001,$Z11))} | D11: {=IF($Z11="","",INDEX('Dữ liệu gộp'!$C$2:$C$1001,$Z11))} | E11: {=IF($Z11="","",INDEX('Dữ liệu gộp'!$D$2:$D$1001,$Z11))} | F11: {=IF($Z11="","",INDEX('Dữ liệu gộp'!$E$2:$E$1001,$Z11))} | G11: {=IF($Z11="","",INDEX('Dữ liệu gộp'!$F$2:$F$1001,$Z11))} | H11: {=IF($Z11="","",INDEX('Dữ liệu gộp'!$H$2:$H$1001,$Z11))} | I11: {=IF($Z11="","",INDEX('Dữ liệu gộp'!$I$2:$I$1001,$Z11))} | J11: {=IF($Z11="","",INDEX('Dữ liệu gộp'!$J$2:$J$1001,$Z11))} | K11: {=IF($Z11="","",INDEX('Dữ liệu gộp'!$K$2:$K$1001,$Z11))} | Z11: =IF($C$4="","",IFERROR(MATCH(2,'Dữ liệu gộp'!$L$2:$L$1001,0),""))
A12: =IF(Z12="","",3) | B12: {=IF($Z12="","",INDEX('Dữ liệu gộp'!$A$2:$A$1001,$Z12))} | C12: {=IF($Z12="","",INDEX('Dữ liệu gộp'!$B$2:$B$1001,$Z12))} | D12: {=IF($Z12="","",INDEX('Dữ liệu gộp'!$C$2:$C$1001,$Z12))} | E12: {=IF($Z12="","",INDEX('Dữ liệu gộp'!$D$2:$D$1001,$Z12))} | F12: {=IF($Z12="","",INDEX('Dữ liệu gộp'!$E$2:$E$1001,$Z12))} | G12: {=IF($Z12="","",INDEX('Dữ liệu gộp'!$F$2:$F$1001,$Z12))} | H12: {=IF($Z12="","",INDEX('Dữ liệu gộp'!$H$2:$H$1001,$Z12))} | I12: {=IF($Z12="","",INDEX('Dữ liệu gộp'!$I$2:$I$1001,$Z12))} | J12: {=IF($Z12="","",INDEX('Dữ liệu gộp'!$J$2:$J$1001,$Z12))} | K12: {=IF($Z12="","",INDEX('Dữ liệu gộp'!$K$2:$K$1001,$Z12))} | Z12: =IF($C$4="","",IFERROR(MATCH(3,'Dữ liệu gộp'!$L$2:$L$1001,0),""))
A13: =IF(Z13="","",4) | B13: {=IF($Z13="","",INDEX('Dữ liệu gộp'!$A$2:$A$1001,$Z13))} | C13: {=IF($Z13="","",INDEX('Dữ liệu gộp'!$B$2:$B$1001,$Z13))} | D13: {=IF($Z13="","",INDEX('Dữ liệu gộp'!$C$2:$C$1001,$Z13))} | E13: {=IF($Z13="","",INDEX('Dữ liệu gộp'!$D$2:$D$1001,$Z13))} | F13: {=IF($Z13="","",INDEX('Dữ liệu gộp'!$E$2:$E$1001,$Z13))} | G13: {=IF($Z13="","",INDEX('Dữ liệu gộp'!$F$2:$F$1001,$Z13))} | H13: {=IF($Z13="","",INDEX('Dữ liệu gộp'!$H$2:$H$1001,$Z13))} | I13: {=IF($Z13="","",INDEX('Dữ liệu gộp'!$I$2:$I$1001,$Z13))} | J13: {=IF($Z13="","",INDEX('Dữ liệu gộp'!$J$2:$J$1001,$Z13))} | K13: {=IF($Z13="","",INDEX('Dữ liệu gộp'!$K$2:$K$1001,$Z13))} | Z13: =IF($C$4="","",IFERROR(MATCH(4,'Dữ liệu gộp'!$L$2:$L$1001,0),""))
A14: =IF(Z14="","",5) | B14: {=IF($Z14="","",INDEX('Dữ liệu gộp'!$A$2:$A$1001,$Z14))} | C14: {=IF($Z14="","",INDEX('Dữ liệu gộp'!$B$2:$B$1001,$Z14))} | D14: {=IF($Z14="","",INDEX('Dữ liệu gộp'!$C$2:$C$1001,$Z14))} | E14: {=IF($Z14="","",INDEX('Dữ liệu gộp'!$D$2:$D$1001,$Z14))} | F14: {=IF($Z14="","",INDEX('Dữ liệu gộp'!$E$2:$E$1001,$Z14))} | G14: {=IF($Z14="","",INDEX('Dữ liệu gộp'!$F$2:$F$1001,$Z14))} | H14: {=IF($Z14="","",INDEX('Dữ liệu gộp'!$H$2:$H$1001,$Z14))} | I14: {=IF($Z14="","",INDEX('Dữ liệu gộp'!$I$2:$I$1001,$Z14))} | J14: {=IF($Z14="","",INDEX('Dữ liệu gộp'!$J$2:$J$1001,$Z14))} | K14: {=IF($Z14="","",INDEX('Dữ liệu gộp'!$K$2:$K$1001,$Z14))} | Z14: =IF($C$4="","",IFERROR(MATCH(5,'Dữ liệu gộp'!$L$2:$L$1001,0),""))
A15: =IF(Z15="","",6) | B15: {=IF($Z15="","",INDEX('Dữ liệu gộp'!$A$2:$A$1001,$Z15))} | C15: {=IF($Z15="","",INDEX('Dữ liệu gộp'!$B$2:$B$1001,$Z15))} | D15: {=IF($Z15="","",INDEX('Dữ liệu gộp'!$C$2:$C$1001,$Z15))} | E15: {=IF($Z15="","",INDEX('Dữ liệu gộp'!$D$2:$D$1001,$Z15))} | F15: {=IF($Z15="","",INDEX('Dữ liệu gộp'!$E$2:$E$1001,$Z15))} | G15: {=IF($Z15="","",INDEX('Dữ liệu gộp'!$F$2:$F$1001,$Z15))} | H15: {=IF($Z15="","",INDEX('Dữ liệu gộp'!$H$2:$H$1001,$Z15))} | I15: {=IF($Z15="","",INDEX('Dữ liệu gộp'!$I$2:$I$1001,$Z15))} | J15: {=IF($Z15="","",INDEX('Dữ liệu gộp'!$J$2:$J$1001,$Z15))} | K15: {=IF($Z15="","",INDEX('Dữ liệu gộp'!$K$2:$K$1001,$Z15))} | Z15: =IF($C$4="","",IFERROR(MATCH(6,'Dữ liệu gộp'!$L$2:$L$1001,0),""))
A16: =IF(Z16="","",7) | B16: {=IF($Z16="","",INDEX('Dữ liệu gộp'!$A$2:$A$1001,$Z16))} | C16: {=IF($Z16="","",INDEX('Dữ liệu gộp'!$B$2:$B$1001,$Z16))} | D16: {=IF($Z16="","",INDEX('Dữ liệu gộp'!$C$2:$C$1001,$Z16))} | E16: {=IF($Z16="","",INDEX('Dữ liệu gộp'!$D$2:$D$1001,$Z16))} | F16: {=IF($Z16="","",INDEX('Dữ liệu gộp'!$E$2:$E$1001,$Z16))} | G16: {=IF($Z16="","",INDEX('Dữ liệu gộp'!$F$2:$F$1001,$Z16))} | H16: {=IF($Z16="","",INDEX('Dữ liệu gộp'!$H$2:$H$1001,$Z16))} | I16: {=IF($Z16="","",INDEX('Dữ liệu gộp'!$I$2:$I$1001,$Z16))} | J16: {=IF($Z16="","",INDEX('Dữ liệu gộp'!$J$2:$J$1001,$Z16))} | K16: {=IF($Z16="","",INDEX('Dữ liệu gộp'!$K$2:$K$1001,$Z16))} | Z16: =IF($C$4="","",IFERROR(MATCH(7,'Dữ liệu gộp'!$L$2:$L$1001,0),""))
A17: =IF(Z17="","",8) | B17: {=IF($Z17="","",INDEX('Dữ liệu gộp'!$A$2:$A$1001,$Z17))} | C17: {=IF($Z17="","",INDEX('Dữ liệu gộp'!$B$2:$B$1001,$Z17))} | D17: {=IF($Z17="","",INDEX('Dữ liệu gộp'!$C$2:$C$1001,$Z17))} | E17: {=IF($Z17="","",INDEX('Dữ liệu gộp'!$D$2:$D$1001,$Z17))} | F17: {=IF($Z17="","",INDEX('Dữ liệu gộp'!$E$2:$E$1001,$Z17))} | G17: {=IF($Z17="","",INDEX('Dữ liệu gộp'!$F$2:$F$1001,$Z17))} | H17: {=IF($Z17="","",INDEX('Dữ liệu gộp'!$H$2:$H$1001,$Z17))} | I17: {=IF($Z17="","",INDEX('Dữ liệu gộp'!$I$2:$I$1001,$Z17))} | J17: {=IF($Z17="","",INDEX('Dữ liệu gộp'!$J$2:$J$1001,$Z17))} | K17: {=IF($Z17="","",INDEX('Dữ liệu gộp'!$K$2:$K$1001,$Z17))} | Z17: =IF($C$4="","",IFERROR(MATCH(8,'Dữ liệu gộp'!$L$2:$L$1001,0),""))
A18: =IF(Z18="","",9) | B18: {=IF($Z18="","",INDEX('Dữ liệu gộp'!$A$2:$A$1001,$Z18))} | C18: {=IF($Z18="","",INDEX('Dữ liệu gộp'!$B$2:$B$1001,$Z18))} | D18: {=IF($Z18="","",INDEX('Dữ liệu gộp'!$C$2:$C$1001,$Z18))} | E18: {=IF($Z18="","",INDEX('Dữ liệu gộp'!$D$2:$D$1001,$Z18))} | F18: {=IF($Z18="","",INDEX('Dữ liệu gộp'!$E$2:$E$1001,$Z18))} | G18: {=IF($Z18="","",INDEX('Dữ liệu gộp'!$F$2:$F$1001,$Z18))} | H18: {=IF($Z18="","",INDEX('Dữ liệu gộp'!$H$2:$H$1001,$Z18))} | I18: {=IF($Z18="","",INDEX('Dữ liệu gộp'!$I$2:$I$1001,$Z18))} | J18: {=IF($Z18="","",INDEX('Dữ liệu gộp'!$J$2:$J$1001,$Z18))} | K18: {=IF($Z18="","",INDEX('Dữ liệu gộp'!$K$2:$K$1001,$Z18))} | Z18: =IF($C$4="","",IFERROR(MATCH(9,'Dữ liệu gộp'!$L$2:$L$1001,0),""))
A19: =IF(Z19="","",10) | B19: {=IF($Z19="","",INDEX('Dữ liệu gộp'!$A$2:$A$1001,$Z19))} | C19: {=IF($Z19="","",INDEX('Dữ liệu gộp'!$B$2:$B$1001,$Z19))} | D19: {=IF($Z19="","",INDEX('Dữ liệu gộp'!$C$2:$C$1001,$Z19))} | E19: {=IF($Z19="","",INDEX('Dữ liệu gộp'!$D$2:$D$1001,$Z19))} | F19: {=IF($Z19="","",INDEX('Dữ liệu gộp'!$E$2:$E$1001,$Z19))} | G19: {=IF($Z19="","",INDEX('Dữ liệu gộp'!$F$2:$F$1001,$Z19))} | H19: {=IF($Z19="","",INDEX('Dữ liệu gộp'!$H$2:$H$1001,$Z19))} | I19: {=IF($Z19="","",INDEX('Dữ liệu gộp'!$I$2:$I$1001,$Z19))} | J19: {=IF($Z19="","",INDEX('Dữ liệu gộp'!$J$2:$J$1001,$Z19))} | K19: {=IF($Z19="","",INDEX('Dữ liệu gộp'!$K$2:$K$1001,$Z19))} | Z19: =IF($C$4="","",IFERROR(MATCH(10,'Dữ liệu gộp'!$L$2:$L$1001,0),""))
A20: =IF(Z20="","",11) | B20: {=IF($Z20="","",INDEX('Dữ liệu gộp'!$A$2:$A$1001,$Z20))} | C20: {=IF($Z20="","",INDEX('Dữ liệu gộp'!$B$2:$B$1001,$Z20))} | D20: {=IF($Z20="","",INDEX('Dữ liệu gộp'!$C$2:$C$1001,$Z20))} | E20: {=IF($Z20="","",INDEX('Dữ liệu gộp'!$D$2:$D$1001,$Z20))} | F20: {=IF($Z20="","",INDEX('Dữ liệu gộp'!$E$2:$E$1001,$Z20))} | G20: {=IF($Z20="","",INDEX('Dữ liệu gộp'!$F$2:$F$1001,$Z20))} | H20: {=IF($Z20="","",INDEX('Dữ liệu gộp'!$H$2:$H$1001,$Z20))} | I20: {=IF($Z20="","",INDEX('Dữ liệu gộp'!$I$2:$I$1001,$Z20))} | J20: {=IF($Z20="","",INDEX('Dữ liệu gộp'!$J$2:$J$1001,$Z20))} | K20: {=IF($Z20="","",INDEX('Dữ liệu gộp'!$K$2:$K$1001,$Z20))} | Z20: =IF($C$4="","",IFERROR(MATCH(11,'Dữ liệu gộp'!$L$2:$L$1001,0),""))
A21: =IF(Z21="","",12) | B21: {=IF($Z21="","",INDEX('Dữ liệu gộp'!$A$2:$A$1001,$Z21))} | C21: {=IF($Z21="","",INDEX('Dữ liệu gộp'!$B$2:$B$1001,$Z21))} | D21: {=IF($Z21="","",INDEX('Dữ liệu gộp'!$C$2:$C$1001,$Z21))} | E21: {=IF($Z21="","",INDEX('Dữ liệu gộp'!$D$2:$D$1001,$Z21))} | F21: {=IF($Z21="","",INDEX('Dữ liệu gộp'!$E$2:$E$1001,$Z21))} | G21: {=IF($Z21="","",INDEX('Dữ liệu gộp'!$F$2:$F$1001,$Z21))} | H21: {=IF($Z21="","",INDEX('Dữ liệu gộp'!$H$2:$H$1001,$Z21))} | I21: {=IF($Z21="","",INDEX('Dữ liệu gộp'!$I$2:$I$1001,$Z21))} | J21: {=IF($Z21="","",INDEX('Dữ liệu gộp'!$J$2:$J$1001,$Z21))} | K21: {=IF($Z21="","",INDEX('Dữ liệu gộp'!$K$2:$K$1001,$Z21))} | Z21: =IF($C$4="","",IFERROR(MATCH(12,'Dữ liệu gộp'!$L$2:$L$1001,0),""))
A22: =IF(Z22="","",13) | B22: {=IF($Z22="","",INDEX('Dữ liệu gộp'!$A$2:$A$1001,$Z22))} | C22: {=IF($Z22="","",INDEX('Dữ liệu gộp'!$B$2:$B$1001,$Z22))} | D22: {=IF($Z22="","",INDEX('Dữ liệu gộp'!$C$2:$C$1001,$Z22))} | E22: {=IF($Z22="","",INDEX('Dữ liệu gộp'!$D$2:$D$1001,$Z22))} | F22: {=IF($Z22="","",INDEX('Dữ liệu gộp'!$E$2:$E$1001,$Z22))} | G22: {=IF($Z22="","",INDEX('Dữ liệu gộp'!$F$2:$F$1001,$Z22))} | H22: {=IF($Z22="","",INDEX('Dữ liệu gộp'!$H$2:$H$1001,$Z22))} | I22: {=IF($Z22="","",INDEX('Dữ liệu gộp'!$I$2:$I$1001,$Z22))} | J22: {=IF($Z22="","",INDEX('Dữ liệu gộp'!$J$2:$J$1001,$Z22))} | K22: {=IF($Z22="","",INDEX('Dữ liệu gộp'!$K$2:$K$1001,$Z22))} | Z22: =IF($C$4="","",IFERROR(MATCH(13,'Dữ liệu gộp'!$L$2:$L$1001,0),""))
A23: =IF(Z23="","",14) | B23: {=IF($Z23="","",INDEX('Dữ liệu gộp'!$A$2:$A$1001,$Z23))} | C23: {=IF($Z23="","",INDEX('Dữ liệu gộp'!$B$2:$B$1001,$Z23))} | D23: {=IF($Z23="","",INDEX('Dữ liệu gộp'!$C$2:$C$1001,$Z23))} | E23: {=IF($Z23="","",INDEX('Dữ liệu gộp'!$D$2:$D$1001,$Z23))} | F23: {=IF($Z23="","",INDEX('Dữ liệu gộp'!$E$2:$E$1001,$Z23))} | G23: {=IF($Z23="","",INDEX('Dữ liệu gộp'!$F$2:$F$1001,$Z23))} | H23: {=IF($Z23="","",INDEX('Dữ liệu gộp'!$H$2:$H$1001,$Z23))} | I23: {=IF($Z23="","",INDEX('Dữ liệu gộp'!$I$2:$I$1001,$Z23))} | J23: {=IF($Z23="","",INDEX('Dữ liệu gộp'!$J$2:$J$1001,$Z23))} | K23: {=IF($Z23="","",INDEX('Dữ liệu gộp'!$K$2:$K$1001,$Z23))} | Z23: =IF($C$4="","",IFERROR(MATCH(14,'Dữ liệu gộp'!$L$2:$L$1001,0),""))
A24: =IF(Z24="","",15) | B24: {=IF($Z24="","",INDEX('Dữ liệu gộp'!$A$2:$A$1001,$Z24))} | C24: {=IF($Z24="","",INDEX('Dữ liệu gộp'!$B$2:$B$1001,$Z24))} | D24: {=IF($Z24="","",INDEX('Dữ liệu gộp'!$C$2:$C$1001,$Z24))} | E24: {=IF($Z24="","",INDEX('Dữ liệu gộp'!$D$2:$D$1001,$Z24))} | F24: {=IF($Z24="","",INDEX('Dữ liệu gộp'!$E$2:$E$1001,$Z24))} | G24: {=IF($Z24="","",INDEX('Dữ liệu gộp'!$F$2:$F$1001,$Z24))} | H24: {=IF($Z24="","",INDEX('Dữ liệu gộp'!$H$2:$H$1001,$Z24))} | I24: {=IF($Z24="","",INDEX('Dữ liệu gộp'!$I$2:$I$1001,$Z24))} | J24: {=IF($Z24="","",INDEX('Dữ liệu gộp'!$J$2:$J$1001,$Z24))} | K24: {=IF($Z24="","",INDEX('Dữ liệu gộp'!$K$2:$K$1001,$Z24))} | Z24: =IF($C$4="","",IFERROR(MATCH(15,'Dữ liệu gộp'!$L$2:$L$1001,0),""))
A25: =IF(Z25="","",16) | B25: {=IF($Z25="","",INDEX('Dữ liệu gộp'!$A$2:$A$1001,$Z25))} | C25: {=IF($Z25="","",INDEX('Dữ liệu gộp'!$B$2:$B$1001,$Z25))} | D25: {=IF($Z25="","",INDEX('Dữ liệu gộp'!$C$2:$C$1001,$Z25))} | E25: {=IF($Z25="","",INDEX('Dữ liệu gộp'!$D$2:$D$1001,$Z25))} | F25: {=IF($Z25="","",INDEX('Dữ liệu gộp'!$E$2:$E$1001,$Z25))} | G25: {=IF($Z25="","",INDEX('Dữ liệu gộp'!$F$2:$F$1001,$Z25))} | H25: {=IF($Z25="","",INDEX('Dữ liệu gộp'!$H$2:$H$1001,$Z25))} | I25: {=IF($Z25="","",INDEX('Dữ liệu gộp'!$I$2:$I$1001,$Z25))} | J25: {=IF($Z25="","",INDEX('Dữ liệu gộp'!$J$2:$J$1001,$Z25))} | K25: {=IF($Z25="","",INDEX('Dữ liệu gộp'!$K$2:$K$1001,$Z25))} | Z25: =IF($C$4="","",IFERROR(MATCH(16,'Dữ liệu gộp'!$L$2:$L$1001,0),""))
A26: =IF(Z26="","",17) | B26: {=IF($Z26="","",INDEX('Dữ liệu gộp'!$A$2:$A$1001,$Z26))} | C26: {=IF($Z26="","",INDEX('Dữ liệu gộp'!$B$2:$B$1001,$Z26))} | D26: {=IF($Z26="","",INDEX('Dữ liệu gộp'!$C$2:$C$1001,$Z26))} | E26: {=IF($Z26="","",INDEX('Dữ liệu gộp'!$D$2:$D$1001,$Z26))} | F26: {=IF($Z26="","",INDEX('Dữ liệu gộp'!$E$2:$E$1001,$Z26))} | G26: {=IF($Z26="","",INDEX('Dữ liệu gộp'!$F$2:$F$1001,$Z26))} | H26: {=IF($Z26="","",INDEX('Dữ liệu gộp'!$H$2:$H$1001,$Z26))} | I26: {=IF($Z26="","",INDEX('Dữ liệu gộp'!$I$2:$I$1001,$Z26))} | J26: {=IF($Z26="","",INDEX('Dữ liệu gộp'!$J$2:$J$1001,$Z26))} | K26: {=IF($Z26="","",INDEX('Dữ liệu gộp'!$K$2:$K$1001,$Z26))} | Z26: =IF($C$4="","",IFERROR(MATCH(17,'Dữ liệu gộp'!$L$2:$L$1001,0),""))
A27: =IF(Z27="","",18) | B27: {=IF($Z27="","",INDEX('Dữ liệu gộp'!$A$2:$A$1001,$Z27))} | C27: {=IF($Z27="","",INDEX('Dữ liệu gộp'!$B$2:$B$1001,$Z27))} | D27: {=IF($Z27="","",INDEX('Dữ liệu gộp'!$C$2:$C$1001,$Z27))} | E27: {=IF($Z27="","",INDEX('Dữ liệu gộp'!$D$2:$D$1001,$Z27))} | F27: {=IF($Z27="","",INDEX('Dữ liệu gộp'!$E$2:$E$1001,$Z27))} | G27: {=IF($Z27="","",INDEX('Dữ liệu gộp'!$F$2:$F$1001,$Z27))} | H27: {=IF($Z27="","",INDEX('Dữ liệu gộp'!$H$2:$H$1001,$Z27))} | I27: {=IF($Z27="","",INDEX('Dữ liệu gộp'!$I$2:$I$1001,$Z27))} | J27: {=IF($Z27="","",INDEX('Dữ liệu gộp'!$J$2:$J$1001,$Z27))} | K27: {=IF($Z27="","",INDEX('Dữ liệu gộp'!$K$2:$K$1001,$Z27))} | Z27: =IF($C$4="","",IFERROR(MATCH(18,'Dữ liệu gộp'!$L$2:$L$1001,0),""))
A28: =IF(Z28="","",19) | B28: {=IF($Z28="","",INDEX('Dữ liệu gộp'!$A$2:$A$1001,$Z28))} | C28: {=IF($Z28="","",INDEX('Dữ liệu gộp'!$B$2:$B$1001,$Z28))} | D28: {=IF($Z28="","",INDEX('Dữ liệu gộp'!$C$2:$C$1001,$Z28))} | E28: {=IF($Z28="","",INDEX('Dữ liệu gộp'!$D$2:$D$1001,$Z28))} | F28: {=IF($Z28="","",INDEX('Dữ liệu gộp'!$E$2:$E$1001,$Z28))} | G28: {=IF($Z28="","",INDEX('Dữ liệu gộp'!$F$2:$F$1001,$Z28))} | H28: {=IF($Z28="","",INDEX('Dữ liệu gộp'!$H$2:$H$1001,$Z28))} | I28: {=IF($Z28="","",INDEX('Dữ liệu gộp'!$I$2:$I$1001,$Z28))} | J28: {=IF($Z28="","",INDEX('Dữ liệu gộp'!$J$2:$J$1001,$Z28))} | K28: {=IF($Z28="","",INDEX('Dữ liệu gộp'!$K$2:$K$1001,$Z28))} | Z28: =IF($C$4="","",IFERROR(MATCH(19,'Dữ liệu gộp'!$L$2:$L$1001,0),""))
A29: =IF(Z29="","",20) | B29: {=IF($Z29="","",INDEX('Dữ liệu gộp'!$A$2:$A$1001,$Z29))} | C29: {=IF($Z29="","",INDEX('Dữ liệu gộp'!$B$2:$B$1001,$Z29))} | D29: {=IF($Z29="","",INDEX('Dữ liệu gộp'!$C$2:$C$1001,$Z29))} | E29: {=IF($Z29="","",INDEX('Dữ liệu gộp'!$D$2:$D$1001,$Z29))} | F29: {=IF($Z29="","",INDEX('Dữ liệu gộp'!$E$2:$E$1001,$Z29))} | G29: {=IF($Z29="","",INDEX('Dữ liệu gộp'!$F$2:$F$1001,$Z29))} | H29: {=IF($Z29="","",INDEX('Dữ liệu gộp'!$H$2:$H$1001,$Z29))} | I29: {=IF($Z29="","",INDEX('Dữ liệu gộp'!$I$2:$I$1001,$Z29))} | J29: {=IF($Z29="","",INDEX('Dữ liệu gộp'!$J$2:$J$1001,$Z29))} | K29: {=IF($Z29="","",INDEX('Dữ liệu gộp'!$K$2:$K$1001,$Z29))} | Z29: =IF($C$4="","",IFERROR(MATCH(20,'Dữ liệu gộp'!$L$2:$L$1001,0),""))
A30: =IF(Z30="","",21) | B30: {=IF($Z30="","",INDEX('Dữ liệu gộp'!$A$2:$A$1001,$Z30))} | C30: {=IF($Z30="","",INDEX('Dữ liệu gộp'!$B$2:$B$1001,$Z30))} | D30: {=IF($Z30="","",INDEX('Dữ liệu gộp'!$C$2:$C$1001,$Z30))} | E30: {=IF($Z30="","",INDEX('Dữ liệu gộp'!$D$2:$D$1001,$Z30))} | F30: {=IF($Z30="","",INDEX('Dữ liệu gộp'!$E$2:$E$1001,$Z30))} | G30: {=IF($Z30="","",INDEX('Dữ liệu gộp'!$F$2:$F$1001,$Z30))} | H30: {=IF($Z30="","",INDEX('Dữ liệu gộp'!$H$2:$H$1001,$Z30))} | I30: {=IF($Z30="","",INDEX('Dữ liệu gộp'!$I$2:$I$1001,$Z30))} | J30: {=IF($Z30="","",INDEX('Dữ liệu gộp'!$J$2:$J$1001,$Z30))} | K30: {=IF($Z30="","",INDEX('Dữ liệu gộp'!$K$2:$K$1001,$Z30))} | Z30: =IF($C$4="","",IFERROR(MATCH(21,'Dữ liệu gộp'!$L$2:$L$1001,0),""))
A31: =IF(Z31="","",22) | B31: {=IF($Z31="","",INDEX('Dữ liệu gộp'!$A$2:$A$1001,$Z31))} | C31: {=IF($Z31="","",INDEX('Dữ liệu gộp'!$B$2:$B$1001,$Z31))} | D31: {=IF($Z31="","",INDEX('Dữ liệu gộp'!$C$2:$C$1001,$Z31))} | E31: {=IF($Z31="","",INDEX('Dữ liệu gộp'!$D$2:$D$1001,$Z31))} | F31: {=IF($Z31="","",INDEX('Dữ liệu gộp'!$E$2:$E$1001,$Z31))} | G31: {=IF($Z31="","",INDEX('Dữ liệu gộp'!$F$2:$F$1001,$Z31))} | H31: {=IF($Z31="","",INDEX('Dữ liệu gộp'!$H$2:$H$1001,$Z31))} | I31: {=IF($Z31="","",INDEX('Dữ liệu gộp'!$I$2:$I$1001,$Z31))} | J31: {=IF($Z31="","",INDEX('Dữ liệu gộp'!$J$2:$J$1001,$Z31))} | K31: {=IF($Z31="","",INDEX('Dữ liệu gộp'!$K$2:$K$1001,$Z31))} | Z31: =IF($C$4="","",IFERROR(MATCH(22,'Dữ liệu gộp'!$L$2:$L$1001,0),""))
A32: =IF(Z32="","",23) | B32: {=IF($Z32="","",INDEX('Dữ liệu gộp'!$A$2:$A$1001,$Z32))} | C32: {=IF($Z32="","",INDEX('Dữ liệu gộp'!$B$2:$B$1001,$Z32))} | D32: {=IF($Z32="","",INDEX('Dữ liệu gộp'!$C$2:$C$1001,$Z32))} | E32: {=IF($Z32="","",INDEX('Dữ liệu gộp'!$D$2:$D$1001,$Z32))} | F32: {=IF($Z32="","",INDEX('Dữ liệu gộp'!$E$2:$E$1001,$Z32))} | G32: {=IF($Z32="","",INDEX('Dữ liệu gộp'!$F$2:$F$1001,$Z32))} | H32: {=IF($Z32="","",INDEX('Dữ liệu gộp'!$H$2:$H$1001,$Z32))} | I32: {=IF($Z32="","",INDEX('Dữ liệu gộp'!$I$2:$I$1001,$Z32))} | J32: {=IF($Z32="","",INDEX('Dữ liệu gộp'!$J$2:$J$1001,$Z32))} | K32: {=IF($Z32="","",INDEX('Dữ liệu gộp'!$K$2:$K$1001,$Z32))} | Z32: =IF($C$4="","",IFERROR(MATCH(23,'Dữ liệu gộp'!$L$2:$L$1001,0),""))
A33: =IF(Z33="","",24) | B33: {=IF($Z33="","",INDEX('Dữ liệu gộp'!$A$2:$A$1001,$Z33))} | C33: {=IF($Z33="","",INDEX('Dữ liệu gộp'!$B$2:$B$1001,$Z33))} | D33: {=IF($Z33="","",INDEX('Dữ liệu gộp'!$C$2:$C$1001,$Z33))} | E33: {=IF($Z33="","",INDEX('Dữ liệu gộp'!$D$2:$D$1001,$Z33))} | F33: {=IF($Z33="","",INDEX('Dữ liệu gộp'!$E$2:$E$1001,$Z33))} | G33: {=IF($Z33="","",INDEX('Dữ liệu gộp'!$F$2:$F$1001,$Z33))} | H33: {=IF($Z33="","",INDEX('Dữ liệu gộp'!$H$2:$H$1001,$Z33))} | I33: {=IF($Z33="","",INDEX('Dữ liệu gộp'!$I$2:$I$1001,$Z33))} | J33: {=IF($Z33="","",INDEX('Dữ liệu gộp'!$J$2:$J$1001,$Z33))} | K33: {=IF($Z33="","",INDEX('Dữ liệu gộp'!$K$2:$K$1001,$Z33))} | Z33: =IF($C$4="","",IFERROR(MATCH(24,'Dữ liệu gộp'!$L$2:$L$1001,0),""))
A34: =IF(Z34="","",25) | B34: {=IF($Z34="","",INDEX('Dữ liệu gộp'!$A$2:$A$1001,$Z34))} | C34: {=IF($Z34="","",INDEX('Dữ liệu gộp'!$B$2:$B$1001,$Z34))} | D34: {=IF($Z34="","",INDEX('Dữ liệu gộp'!$C$2:$C$1001,$Z34))} | E34: {=IF($Z34="","",INDEX('Dữ liệu gộp'!$D$2:$D$1001,$Z34))} | F34: {=IF($Z34="","",INDEX('Dữ liệu gộp'!$E$2:$E$1001,$Z34))} | G34: {=IF($Z34="","",INDEX('Dữ liệu gộp'!$F$2:$F$1001,$Z34))} | H34: {=IF($Z34="","",INDEX('Dữ liệu gộp'!$H$2:$H$1001,$Z34))} | I34: {=IF($Z34="","",INDEX('Dữ liệu gộp'!$I$2:$I$1001,$Z34))} | J34: {=IF($Z34="","",INDEX('Dữ liệu gộp'!$J$2:$J$1001,$Z34))} | K34: {=IF($Z34="","",INDEX('Dữ liệu gộp'!$K$2:$K$1001,$Z34))} | Z34: =IF($C$4="","",IFERROR(MATCH(25,'Dữ liệu gộp'!$L$2:$L$1001,0),""))
A35: =IF(Z35="","",26) | B35: {=IF($Z35="","",INDEX('Dữ liệu gộp'!$A$2:$A$1001,$Z35))} | C35: {=IF($Z35="","",INDEX('Dữ liệu gộp'!$B$2:$B$1001,$Z35))} | D35: {=IF($Z35="","",INDEX('Dữ liệu gộp'!$C$2:$C$1001,$Z35))} | E35: {=IF($Z35="","",INDEX('Dữ liệu gộp'!$D$2:$D$1001,$Z35))} | F35: {=IF($Z35="","",INDEX('Dữ liệu gộp'!$E$2:$E$1001,$Z35))} | G35: {=IF($Z35="","",INDEX('Dữ liệu gộp'!$F$2:$F$1001,$Z35))} | H35: {=IF($Z35="","",INDEX('Dữ liệu gộp'!$H$2:$H$1001,$Z35))} | I35: {=IF($Z35="","",INDEX('Dữ liệu gộp'!$I$2:$I$1001,$Z35))} | J35: {=IF($Z35="","",INDEX('Dữ liệu gộp'!$J$2:$J$1001,$Z35))} | K35: {=IF($Z35="","",INDEX('Dữ liệu gộp'!$K$2:$K$1001,$Z35))} | Z35: =IF($C$4="","",IFERROR(MATCH(26,'Dữ liệu gộp'!$L$2:$L$1001,0),""))
A36: =IF(Z36="","",27) | B36: {=IF($Z36="","",INDEX('Dữ liệu gộp'!$A$2:$A$1001,$Z36))} | C36: {=IF($Z36="","",INDEX('Dữ liệu gộp'!$B$2:$B$1001,$Z36))} | D36: {=IF($Z36="","",INDEX('Dữ liệu gộp'!$C$2:$C$1001,$Z36))} | E36: {=IF($Z36="","",INDEX('Dữ liệu gộp'!$D$2:$D$1001,$Z36))} | F36: {=IF($Z36="","",INDEX('Dữ liệu gộp'!$E$2:$E$1001,$Z36))} | G36: {=IF($Z36="","",INDEX('Dữ liệu gộp'!$F$2:$F$1001,$Z36))} | H36: {=IF($Z36="","",INDEX('Dữ liệu gộp'!$H$2:$H$1001,$Z36))} | I36: {=IF($Z36="","",INDEX('Dữ liệu gộp'!$I$2:$I$1001,$Z36))} | J36: {=IF($Z36="","",INDEX('Dữ liệu gộp'!$J$2:$J$1001,$Z36))} | K36: {=IF($Z36="","",INDEX('Dữ liệu gộp'!$K$2:$K$1001,$Z36))} | Z36: =IF($C$4="","",IFERROR(MATCH(27,'Dữ liệu gộp'!$L$2:$L$1001,0),""))
A37: =IF(Z37="","",28) | B37: {=IF($Z37="","",INDEX('Dữ liệu gộp'!$A$2:$A$1001,$Z37))} | C37: {=IF($Z37="","",INDEX('Dữ liệu gộp'!$B$2:$B$1001,$Z37))} | D37: {=IF($Z37="","",INDEX('Dữ liệu gộp'!$C$2:$C$1001,$Z37))} | E37: {=IF($Z37="","",INDEX('Dữ liệu gộp'!$D$2:$D$1001,$Z37))} | F37: {=IF($Z37="","",INDEX('Dữ liệu gộp'!$E$2:$E$1001,$Z37))} | G37: {=IF($Z37="","",INDEX('Dữ liệu gộp'!$F$2:$F$1001,$Z37))} | H37: {=IF($Z37="","",INDEX('Dữ liệu gộp'!$H$2:$H$1001,$Z37))} | I37: {=IF($Z37="","",INDEX('Dữ liệu gộp'!$I$2:$I$1001,$Z37))} | J37: {=IF($Z37="","",INDEX('Dữ liệu gộp'!$J$2:$J$1001,$Z37))} | K37: {=IF($Z37="","",INDEX('Dữ liệu gộp'!$K$2:$K$1001,$Z37))} | Z37: =IF($C$4="","",IFERROR(MATCH(28,'Dữ liệu gộp'!$L$2:$L$1001,0),""))
A38: =IF(Z38="","",29) | B38: {=IF($Z38="","",INDEX('Dữ liệu gộp'!$A$2:$A$1001,$Z38))} | C38: {=IF($Z38="","",INDEX('Dữ liệu gộp'!$B$2:$B$1001,$Z38))} | D38: {=IF($Z38="","",INDEX('Dữ liệu gộp'!$C$2:$C$1001,$Z38))} | E38: {=IF($Z38="","",INDEX('Dữ liệu gộp'!$D$2:$D$1001,$Z38))} | F38: {=IF($Z38="","",INDEX('Dữ liệu gộp'!$E$2:$E$1001,$Z38))} | G38: {=IF($Z38="","",INDEX('Dữ liệu gộp'!$F$2:$F$1001,$Z38))} | H38: {=IF($Z38="","",INDEX('Dữ liệu gộp'!$H$2:$H$1001,$Z38))} | I38: {=IF($Z38="","",INDEX('Dữ liệu gộp'!$I$2:$I$1001,$Z38))} | J38: {=IF($Z38="","",INDEX('Dữ liệu gộp'!$J$2:$J$1001,$Z38))} | K38: {=IF($Z38="","",INDEX('Dữ liệu gộp'!$K$2:$K$1001,$Z38))} | Z38: =IF($C$4="","",IFERROR(MATCH(29,'Dữ liệu gộp'!$L$2:$L$1001,0),""))
A39: =IF(Z39="","",30) | B39: {=IF($Z39="","",INDEX('Dữ liệu gộp'!$A$2:$A$1001,$Z39))} | C39: {=IF($Z39="","",INDEX('Dữ liệu gộp'!$B$2:$B$1001,$Z39))} | D39: {=IF($Z39="","",INDEX('Dữ liệu gộp'!$C$2:$C$1001,$Z39))} | E39: {=IF($Z39="","",INDEX('Dữ liệu gộp'!$D$2:$D$1001,$Z39))} | F39: {=IF($Z39="","",INDEX('Dữ liệu gộp'!$E$2:$E$1001,$Z39))} | G39: {=IF($Z39="","",INDEX('Dữ liệu gộp'!$F$2:$F$1001,$Z39))} | H39: {=IF($Z39="","",INDEX('Dữ liệu gộp'!$H$2:$H$1001,$Z39))} | I39: {=IF($Z39="","",INDEX('Dữ liệu gộp'!$I$2:$I$1001,$Z39))} | J39: {=IF($Z39="","",INDEX('Dữ liệu gộp'!$J$2:$J$1001,$Z39))} | K39: {=IF($Z39="","",INDEX('Dữ liệu gộp'!$K$2:$K$1001,$Z39))} | Z39: =IF($C$4="","",IFERROR(MATCH(30,'Dữ liệu gộp'!$L$2:$L$1001,0),""))
A40: =IF(Z40="","",31) | B40: {=IF($Z40="","",INDEX('Dữ liệu gộp'!$A$2:$A$1001,$Z40))} | C40: {=IF($Z40="","",INDEX('Dữ liệu gộp'!$B$2:$B$1001,$Z40))} | D40: {=IF($Z40="","",INDEX('Dữ liệu gộp'!$C$2:$C$1001,$Z40))} | E40: {=IF($Z40="","",INDEX('Dữ liệu gộp'!$D$2:$D$1001,$Z40))} | F40: {=IF($Z40="","",INDEX('Dữ liệu gộp'!$E$2:$E$1001,$Z40))} | G40: {=IF($Z40="","",INDEX('Dữ liệu gộp'!$F$2:$F$1001,$Z40))} | H40: {=IF($Z40="","",INDEX('Dữ liệu gộp'!$H$2:$H$1001,$Z40))} | I40: {=IF($Z40="","",INDEX('Dữ liệu gộp'!$I$2:$I$1001,$Z40))} | J40: {=IF($Z40="","",INDEX('Dữ liệu gộp'!$J$2:$J$1001,$Z40))} | K40: {=IF($Z40="","",INDEX('Dữ liệu gộp'!$K$2:$K$1001,$Z40))} | Z40: =IF($C$4="","",IFERROR(MATCH(31,'Dữ liệu gộp'!$L$2:$L$1001,0),""))
A41: =IF(Z41="","",32) | B41: {=IF($Z41="","",INDEX('Dữ liệu gộp'!$A$2:$A$1001,$Z41))} | C41: {=IF($Z41="","",INDEX('Dữ liệu gộp'!$B$2:$B$1001,$Z41))} | D41: {=IF($Z41="","",INDEX('Dữ liệu gộp'!$C$2:$C$1001,$Z41))} | E41: {=IF($Z41="","",INDEX('Dữ liệu gộp'!$D$2:$D$1001,$Z41))} | F41: {=IF($Z41="","",INDEX('Dữ liệu gộp'!$E$2:$E$1001,$Z41))} | G41: {=IF($Z41="","",INDEX('Dữ liệu gộp'!$F$2:$F$1001,$Z41))} | H41: {=IF($Z41="","",INDEX('Dữ liệu gộp'!$H$2:$H$1001,$Z41))} | I41: {=IF($Z41="","",INDEX('Dữ liệu gộp'!$I$2:$I$1001,$Z41))} | J41: {=IF($Z41="","",INDEX('Dữ liệu gộp'!$J$2:$J$1001,$Z41))} | K41: {=IF($Z41="","",INDEX('Dữ liệu gộp'!$K$2:$K$1001,$Z41))} | Z41: =IF($C$4="","",IFERROR(MATCH(32,'Dữ liệu gộp'!$L$2:$L$1001,0),""))
...

Sheet Người sử dụng
A1: DANH SÁCH NHÂN VIÊN ĐƯỢC BÀN GIAO TÀI NGUYÊN – KHỐI MKT
A2: Trưởng ban khai nhân sự của ban mình tại đây TRƯỚC, sau đó mới chọn tên ở cột "Người được bàn giao" trong tab của ban.
A3: Trùng tên: ghi thêm ban hoặc ký hiệu để phân biệt, ví dụ "Nguyễn Thu Hà (ADS)". Cột xám tự tính, không cần điền.
A4: STT | B4: Mã nhân viên | C4: Họ tên | D4: Ban | E4: Chức vụ | F4: SĐT | G4: Email công ty | H4: Trạng thái | I4: Ngày vào làm | J4: Ngày nghỉ / chuyển ban | K4: Số tài nguyên đang giữ | L4: Ghi chú
A5: =SUBTOTAL(103,$B$5:B5) -> 1 | B5: M062HUY | C5: ĐỖ VIẾT HUY | D5: Phòng Tài nguyên | E5: Chuyên Viên | H5: Đang làm | K5: =IF(C5="","",COUNTIF(ADS!$G$6:$G$319,C5)+COUNTIF('Biên Tập'!$G$6:$G$205,C5)+COUNTIF('Thiết Kế'!$G$6:$G$205,C5)+COUNTIF('Media Dựng'!$G$6:$G$205,C5)+COUNTIF('PR Thương Hiệu'!$G$6:$G$205,C5)) -> 2
A6: =SUBTOTAL(103,$B$5:B6) -> 2 | B6: M061HOANG | C6: PHƯƠNG VIỆT HOÀNG | D6: Phòng Tài nguyên | E6: Chuyên Viên | H6: Đang làm | K6: =IF(C6="","",COUNTIF(ADS!$G$6:$G$319,C6)+COUNTIF('Biên Tập'!$G$6:$G$205,C6)+COUNTIF('Thiết Kế'!$G$6:$G$205,C6)+COUNTIF('Media Dựng'!$G$6:$G$205,C6)+COUNTIF('PR Thương Hiệu'!$G$6:$G$205,C6)) -> 30
A7: =SUBTOTAL(103,$B$5:B7) -> 2 | D7: ADS | H7: Đang làm | K7: =IF(C7="","",COUNTIF(ADS!$G$6:$G$319,C7)+COUNTIF('Biên Tập'!$G$6:$G$205,C7)+COUNTIF('Thiết Kế'!$G$6:$G$205,C7)+COUNTIF('Media Dựng'!$G$6:$G$205,C7)+COUNTIF('PR Thương Hiệu'!$G$6:$G$205,C7))
A8: =SUBTOTAL(103,$B$5:B8) -> 2 | D8: Media Dựng | H8: Đang làm | K8: =IF(C8="","",COUNTIF(ADS!$G$6:$G$319,C8)+COUNTIF('Biên Tập'!$G$6:$G$205,C8)+COUNTIF('Thiết Kế'!$G$6:$G$205,C8)+COUNTIF('Media Dựng'!$G$6:$G$205,C8)+COUNTIF('PR Thương Hiệu'!$G$6:$G$205,C8))
A9: =SUBTOTAL(103,$B$5:B9) -> 2 | K9: =IF(C9="","",COUNTIF(ADS!$G$6:$G$319,C9)+COUNTIF('Biên Tập'!$G$6:$G$205,C9)+COUNTIF('Thiết Kế'!$G$6:$G$205,C9)+COUNTIF('Media Dựng'!$G$6:$G$205,C9)+COUNTIF('PR Thương Hiệu'!$G$6:$G$205,C9))
A10: =SUBTOTAL(103,$B$5:B10) -> 2 | K10: =IF(C10="","",COUNTIF(ADS!$G$6:$G$319,C10)+COUNTIF('Biên Tập'!$G$6:$G$205,C10)+COUNTIF('Thiết Kế'!$G$6:$G$205,C10)+COUNTIF('Media Dựng'!$G$6:$G$205,C10)+COUNTIF('PR Thương Hiệu'!$G$6:$G$205,C10))
A11: =SUBTOTAL(103,$B$5:B11) -> 3 | B11: M011HUY | C11: NGÔ TRỌNG HUY | D11: ADS | E11: TP MKT SG | H11: Đang làm | K11: =IF(C11="","",COUNTIF(ADS!$G$6:$G$319,C11)+COUNTIF('Biên Tập'!$G$6:$G$205,C11)+COUNTIF('Thiết Kế'!$G$6:$G$205,C11)+COUNTIF('Media Dựng'!$G$6:$G$205,C11)+COUNTIF('PR Thương Hiệu'!$G$6:$G$205,C11)) -> 31
A12: =SUBTOTAL(103,$B$5:B12) -> 4 | B12: M014TUNG | C12: ĐỖ SƠN TÙNG | D12: ADS | E12: Chuyên viên | H12: Đang làm
A13: =SUBTOTAL(103,$B$5:B13) -> 5 | B13: M015DUONG | C13: ĐÀO ĐÌNH DƯƠNG | D13: ADS | E13: Chuyên viên | H13: Đang làm
A14: =SUBTOTAL(103,$B$5:B14) -> 6 | B14: M039NAM | C14: PHẠM GIANG NAM | D14: ADS | E14: Chuyên viên | F14: 0338509770 | G14: nam.phamgiang@apmtech.vn | H14: Đang làm
A15: =SUBTOTAL(103,$B$5:B15) -> 7 | B15: M064NGOC | C15: NGUYỄN MẠNH NGỌC | D15: ADS | E15: Chuyên viên | H15: Thử việc
A16: =SUBTOTAL(103,$B$5:B16) -> 8 | B16: M052THANG | C16: PHẠM NGỌC THẮNG | D16: ADS | E16: Chuyên viên | H16: Đang làm
A17: =SUBTOTAL(103,$B$5:B17) -> 9 | B17: M048KIEN | C17: PHẠM VĂN KIÊN | D17: ADS | E17: Chuyên viên | H17: Đang làm
A18: =SUBTOTAL(103,$B$5:B18) -> 10 | B18: M016ANH | C18: HOÀNG ANH | D18: ADS | E18: Chuyên viên | H18: Đang làm
A19: =SUBTOTAL(103,$B$5:B19) -> 11 | B19: M001DUNG | C19: NGUYỄN XUÂN DŨNG | D19: ADS | E19: TP MKT HN | H19: Đang làm | K19: =IF(C19="","",COUNTIF(ADS!$G$6:$G$319,C19)+COUNTIF('Biên Tập'!$G$6:$G$205,C19)+COUNTIF('Thiết Kế'!$G$6:$G$205,C19)+COUNTIF('Media Dựng'!$G$6:$G$205,C19)+COUNTIF('PR Thương Hiệu'!$G$6:$G$205,C19)) -> 38
A20: =SUBTOTAL(103,$B$5:B20) -> 12 | B20: M003HIEP | C20: TRẦN HIỆP | D20: ADS | E20: Chuyên viên | H20: Đang làm | K20: =IF(C20="","",COUNTIF(ADS!$G$6:$G$319,C20)+COUNTIF('Biên Tập'!$G$6:$G$205,C20)+COUNTIF('Thiết Kế'!$G$6:$G$205,C20)+COUNTIF('Media Dựng'!$G$6:$G$205,C20)+COUNTIF('PR Thương Hiệu'!$G$6:$G$205,C20)) -> 17
A21: =SUBTOTAL(103,$B$5:B21) -> 13 | B21: M005DUC | C21: BÙI ĐÌNH ĐỨC | D21: ADS | E21: Chuyên viên | H21: Đang làm | K21: =IF(C21="","",COUNTIF(ADS!$G$6:$G$319,C21)+COUNTIF('Biên Tập'!$G$6:$G$205,C21)+COUNTIF('Thiết Kế'!$G$6:$G$205,C21)+COUNTIF('Media Dựng'!$G$6:$G$205,C21)+COUNTIF('PR Thương Hiệu'!$G$6:$G$205,C21)) -> 25
A22: =SUBTOTAL(103,$B$5:B22) -> 14 | B22: M046DUC | C22: VƯƠNG ANH ĐỨC | D22: ADS | E22: Chuyên viên | F22: 0986963706 | G22: duc.vuonganh@apmtech.vn | H22: Đang làm | K22: =IF(C22="","",COUNTIF(ADS!$G$6:$G$319,C22)+COUNTIF('Biên Tập'!$G$6:$G$205,C22)+COUNTIF('Thiết Kế'!$G$6:$G$205,C22)+COUNTIF('Media Dựng'!$G$6:$G$205,C22)+COUNTIF('PR Thương Hiệu'!$G$6:$G$205,C22)) -> 18
A23: =SUBTOTAL(103,$B$5:B23) -> 15 | B23: M043NGUYEN | C23: NGUYỄN QUANG NGUYÊN | D23: ADS | E23: Chuyên viên | H23: Đang làm | K23: =IF(C23="","",COUNTIF(ADS!$G$6:$G$319,C23)+COUNTIF('Biên Tập'!$G$6:$G$205,C23)+COUNTIF('Thiết Kế'!$G$6:$G$205,C23)+COUNTIF('Media Dựng'!$G$6:$G$205,C23)+COUNTIF('PR Thương Hiệu'!$G$6:$G$205,C23)) -> 30
A24: =SUBTOTAL(103,$B$5:B24) -> 16 | B24: E039NAM | C24: HỒ CHÍ NAM | D24: Media | E24: Trưởng nhóm Quay/dựng | F24: 0934546727 | G24: nam.hochi@apmtech.vn | H24: Đang làm | K24: =IF(C24="","",COUNTIF(ADS!$G$6:$G$319,C24)+COUNTIF('Biên Tập'!$G$6:$G$205,C24)+COUNTIF('Thiết Kế'!$G$6:$G$205,C24)+COUNTIF('Media Dựng'!$G$6:$G$205,C24)+COUNTIF('PR Thương Hiệu'!$G$6:$G$205,C24)) -> 20
A25: =SUBTOTAL(103,$B$5:B25) -> 17 | B25: P036HAO | C25: BÙI MỸ HẢO | D25: PR | E25: Chuyên viên | F25: 0355848047 | G25: hao.buimy@apmtech.vn | H25: Đang làm | K25: =IF(C25="","",COUNTIF(ADS!$G$6:$G$319,C25)+COUNTIF('Biên Tập'!$G$6:$G$205,C25)+COUNTIF('Thiết Kế'!$G$6:$G$205,C25)+COUNTIF('Media Dựng'!$G$6:$G$205,C25)+COUNTIF('PR Thương Hiệu'!$G$6:$G$205,C25)) -> 1
A26: =SUBTOTAL(103,$B$5:B26) -> 18 | B26: P040HIEU | C26: HOÀNG MINH HIẾU | D26: PR | E26: Chuyên viên | F26: 0934623853 | G26: hieu.hoangminh@apmtech.vn | H26: Đang làm | K26: =IF(C26="","",COUNTIF(ADS!$G$6:$G$319,C26)+COUNTIF('Biên Tập'!$G$6:$G$205,C26)+COUNTIF('Thiết Kế'!$G$6:$G$205,C26)+COUNTIF('Media Dựng'!$G$6:$G$205,C26)+COUNTIF('PR Thương Hiệu'!$G$6:$G$205,C26)) -> 2
A27: =SUBTOTAL(103,$B$5:B27) -> 19 | B27: P006QUYEN | C27: LÊ HẠNH QUYÊN | D27: PR | E27: Chuyên viên | F27: 0948347936 | G27: quyen.lehanh@apmtech.vn | H27: Đang làm | K27: =IF(C27="","",COUNTIF(ADS!$G$6:$G$319,C27)+COUNTIF('Biên Tập'!$G$6:$G$205,C27)+COUNTIF('Thiết Kế'!$G$6:$G$205,C27)+COUNTIF('Media Dựng'!$G$6:$G$205,C27)+COUNTIF('PR Thương Hiệu'!$G$6:$G$205,C27)) -> 6
A28: =SUBTOTAL(103,$B$5:B28) -> 20 | B28: P047HOAI | C28: ĐỖ THỊ THU HOÀI | D28: PR | E28: Chuyên viên | F28: 0343503876 | G28: hoai.dothu@apmtech.vn | H28: Đang làm | K28: =IF(C28="","",COUNTIF(ADS!$G$6:$G$319,C28)+COUNTIF('Biên Tập'!$G$6:$G$205,C28)+COUNTIF('Thiết Kế'!$G$6:$G$205,C28)+COUNTIF('Media Dựng'!$G$6:$G$205,C28)+COUNTIF('PR Thương Hiệu'!$G$6:$G$205,C28)) -> 4
A29: =SUBTOTAL(103,$B$5:B29) -> 21 | B29: P029PHUONG | C29: PHÙNG HOÀNG PHƯỢNG | D29: PR | E29: Chuyên viên | F29: 0385994534 | G29: phuong.phunghoang@apmtech.vn | H29: Đang làm | K29: =IF(C29="","",COUNTIF(ADS!$G$6:$G$319,C29)+COUNTIF('Biên Tập'!$G$6:$G$205,C29)+COUNTIF('Thiết Kế'!$G$6:$G$205,C29)+COUNTIF('Media Dựng'!$G$6:$G$205,C29)+COUNTIF('PR Thương Hiệu'!$G$6:$G$205,C29)) -> 4
A30: =SUBTOTAL(103,$B$5:B30) -> 22 | B30: E069ANH | C30: TRẦN MINH ANH | D30: PR | E30: Chuyên viên | F30: 0373907602 | G30: anh.tranminh@apmtech.vn | H30: Đang làm | K30: 0
A31: =SUBTOTAL(103,$B$5:B31) -> 23 | B31: E041TUYET | C31: NGUYỄN THỊ ÁNH TUYẾT | D31: PR | E31: Chuyên viên | F31: 0333049212 | G31: tuyet.nguyenanh@apmtech.vn | H31: Đang làm | K31: =IF(C31="","",COUNTIF(ADS!$G$6:$G$319,C31)+COUNTIF('Biên Tập'!$G$6:$G$205,C31)+COUNTIF('Thiết Kế'!$G$6:$G$205,C31)+COUNTIF('Media Dựng'!$G$6:$G$205,C31)+COUNTIF('PR Thương Hiệu'!$G$6:$G$205,C31)) -> 14
A32: =SUBTOTAL(103,$B$5:B32) -> 24 | B32: P008LUU | C32: BÙI THỊ LƯU | D32: PR | E32: Chuyên viên | F32: 0818407250 | G32: luu.bui@apmtech | H32: Đang làm | K32: =IF(C32="","",COUNTIF(ADS!$G$6:$G$319,C32)+COUNTIF('Biên Tập'!$G$6:$G$205,C32)+COUNTIF('Thiết Kế'!$G$6:$G$205,C32)+COUNTIF('Media Dựng'!$G$6:$G$205,C32)+COUNTIF('PR Thương Hiệu'!$G$6:$G$205,C32)) -> 3
A33: =SUBTOTAL(103,$B$5:B33) -> 25 | B33: P046LINH | C33: LÊ HUYỀN LINH | D33: PR | E33: Chuyên viên | F33: 0987071396 | G33: linh.lehuyen@apmtech.vn | H33: Đang làm | K33: =IF(C33="","",COUNTIF(ADS!$G$6:$G$319,C33)+COUNTIF('Biên Tập'!$G$6:$G$205,C33)+COUNTIF('Thiết Kế'!$G$6:$G$205,C33)+COUNTIF('Media Dựng'!$G$6:$G$205,C33)+COUNTIF('PR Thương Hiệu'!$G$6:$G$205,C33)) -> 1
A34: =SUBTOTAL(103,$B$5:B34) -> 26 | B34: P055HANG | C34: BÙI THỊ THANH HẰNG | D34: PR | E34: Chuyên viên | F34: 0373208609 | G34: hang.buithanh@apmtech.vn | H34: Đang làm | K34: 2
A35: =SUBTOTAL(103,$B$5:B35) -> 27 | B35: E051LONG | C35: MAI TÙNG LONG | D35: Media | E35: TP MEDIA | F35: 0963786970 | G35: long.maitung@apmtech.vn | H35: Đang làm | K35: =IF(C35="","",COUNTIF(ADS!$G$6:$G$319,C35)+COUNTIF('Biên Tập'!$G$6:$G$205,C35)+COUNTIF('Thiết Kế'!$G$6:$G$205,C35)+COUNTIF('Media Dựng'!$G$6:$G$205,C35)+COUNTIF('PR Thương Hiệu'!$G$6:$G$205,C35)) -> 6
A36: =SUBTOTAL(103,$B$5:B36) -> 28 | B36: E061HAI | C36: NGUYỄN HOÀNG HẢI | D36: Media | E36: Chuyên viên | F36: 0363186570 | G36: hai.nguyenhoang@apmtech.vn | H36: Đang làm | K36: =IF(C36="","",COUNTIF(ADS!$G$6:$G$319,C36)+COUNTIF('Biên Tập'!$G$6:$G$205,C36)+COUNTIF('Thiết Kế'!$G$6:$G$205,C36)+COUNTIF('Media Dựng'!$G$6:$G$205,C36)+COUNTIF('PR Thương Hiệu'!$G$6:$G$205,C36)) -> 2
A37: =SUBTOTAL(103,$B$5:B37) -> 29 | B37: E068TANG | C37: NGUYỄN MẠNH TĂNG | D37: Media | E37: Chuyên viên | H37: Đang làm | K37: =IF(C37="","",COUNTIF(ADS!$G$6:$G$319,C37)+COUNTIF('Biên Tập'!$G$6:$G$205,C37)+COUNTIF('Thiết Kế'!$G$6:$G$205,C37)+COUNTIF('Media Dựng'!$G$6:$G$205,C37)+COUNTIF('PR Thương Hiệu'!$G$6:$G$205,C37)) -> 3
A38: =SUBTOTAL(103,$B$5:B38) -> 30 | B38: E065ANH | C38: ĐỖ THÚY ANH | D38: Media | H38: Đang làm | K38: =IF(C38="","",COUNTIF(ADS!$G$6:$G$319,C38)+COUNTIF('Biên Tập'!$G$6:$G$205,C38)+COUNTIF('Thiết Kế'!$G$6:$G$205,C38)+COUNTIF('Media Dựng'!$G$6:$G$205,C38)+COUNTIF('PR Thương Hiệu'!$G$6:$G$205,C38)) -> 2
A39: =SUBTOTAL(103,$B$5:B39) -> 31 | B39: E067TRANG | C39: NGUYỄN THỊ TRANG | D39: Media | H39: Đang làm | K39: =IF(C39="","",COUNTIF(ADS!$G$6:$G$319,C39)+COUNTIF('Biên Tập'!$G$6:$G$205,C39)+COUNTIF('Thiết Kế'!$G$6:$G$205,C39)+COUNTIF('Media Dựng'!$G$6:$G$205,C39)+COUNTIF('PR Thương Hiệu'!$G$6:$G$205,C39)) -> 3
A40: =SUBTOTAL(103,$B$5:B40) -> 32 | B40: E071TRANG | C40: NGUYỄN THỊ KIỀU TRANG | D40: Media | E40: Chuyên viên | F40: 0963 95 6336 | G40: huyngotrong.gtg@gmail.com | H40: Thử việc | K40: =IF(C40="","",COUNTIF(ADS!$G$6:$G$319,C40)+COUNTIF('Biên Tập'!$G$6:$G$205,C40)+COUNTIF('Thiết Kế'!$G$6:$G$205,C40)+COUNTIF('Media Dựng'!$G$6:$G$205,C40)+COUNTIF('PR Thương Hiệu'!$G$6:$G$205,C40)) -> 2
...

Sheet ADS
A1: KHAI BÁO TÀI NGUYÊN SỐ – BAN ADS
A2: Người khai báo: | E2: Ngày khai báo:
A3: Lưu ý: KHÔNG ghi mật khẩu. Ô xanh nhạt = ban điền · Cột xám = tự tính · Cột hồng = Phòng Tài nguyên điền. Người được bàn giao phải có trong tab "Người sử dụng".
A4: THÔNG TIN TÀI NGUYÊN (ban tự khai) | T4: TRẠNG THÁI THEO THÁNG (Phòng Tài nguyên cập nhật khi rà soát)
A5: STT | B5: Mã tài nguyên | C5: Loại tài nguyên | D5: ID tài nguyên | E5: Tên tài nguyên | F5: Link | G5: Người được bàn giao (đang quản lý) | H5: Mã NV | I5: Trạng thái người dùng | J5: Quyền đang có | K5: Email đăng ký | L5: SĐT đăng ký | M5: Bảo mật 2 lớp | N5: Ai đang giữ mã 2 lớp | O5: Nguồn gốc | P5: Ngày bắt đầu dùng | Q5: Mục đích sử dụng | R5: Bàn giao về Tài nguyên | S5: Ghi chú | T5: T10/2026 | U5: T11/2026 | V5: T12/2026 | W5: T01/2027 | X5: T02/2027 | Y5: T03/2027 | Z5: T04/2027 | AA5: T05/2027 | AB5: T06/2027 | AC5: T07/2027 | AD5: T08/2027 | AE5: T09/2027
A6: =IF(C6="","",ROW()-5) -> 1 | B6: =IF(C6="","","ADS-"&TEXT(ROW()-5,"000")) -> ADS-001 | C6: Via | D6: 12356489755 | E6: Via Ads 1 | F6: abcxyz.com | G6: ĐỖ VIẾT HUY | H6: {=IFERROR(_xlfn.XLOOKUP(G6:G1230,'Người sử dụng'!$C$4:$C1230,'Người sử dụng'!$B$4:$B1230),"")} -> M062HUY | I6: {=IF(G6="","",IFERROR(INDEX('Người sử dụng'!$H$5:$H$140,MATCH(G6,'Người sử dụng'!$C$5:$C$140,0)),"Chưa có trong DS"))} -> Đang làm | J6: Chủ sở hữu / Admin | O6: Công ty cấp | Q6: Chạy Ads | R6: Đã bàn giao
A7: =IF(C7="","",ROW()-5) -> 2 | B7: =IF(C7="","","ADS-"&TEXT(ROW()-5,"000")) -> ADS-002 | C7: AI | D7: dsffgdg | E7: AI claude | G7: PHƯƠNG VIỆT HOÀNG | H7: M061HOANG | I7: {=IF(G7="","",IFERROR(INDEX('Người sử dụng'!$H$5:$H$140,MATCH(G7,'Người sử dụng'!$C$5:$C$140,0)),"Chưa có trong DS"))} -> Đang làm
A8: =IF(C8="","",ROW()-5) -> 3 | B8: =IF(C8="","","ADS-"&TEXT(ROW()-5,"000")) -> ADS-003 | C8: Page | D8: df6454655 | E8: fdgdfghf | F8: fghfhfgh | G8: PHƯƠNG VIỆT HOÀNG | H8: M061HOANG | I8: {=IF(G8="","",IFERROR(INDEX('Người sử dụng'!$H$5:$H$140,MATCH(G8,'Người sử dụng'!$C$5:$C$140,0)),"Chưa có trong DS"))} -> Đang làm | J8: Chủ sở hữu / Admin | O8: Nhận lại từ người khác | Q8: chạy ads | R8: Chưa bàn giao
A9: =IF(C9="","",ROW()-5) -> 4 | B9: =IF(C9="","","ADS-"&TEXT(ROW()-5,"000")) -> ADS-004 | C9: Nhóm | I9: {=IF(G9="","",IFERROR(INDEX('Người sử dụng'!$H$5:$H$140,MATCH(G9,'Người sử dụng'!$C$5:$C$140,0)),"Chưa có trong DS"))}
A10: =IF(C10="","",ROW()-5) -> 5 | B10: =IF(C10="","","ADS-"&TEXT(ROW()-5,"000")) -> ADS-005 | C10: Via | D10: 100068861280350 | E10: Via | F10: https://www.facebook.com/profile.php?id=100068861280350 | G10: NGUYỄN XUÂN DŨNG | H10: M001DUNG | I10: {=IF(G10="","",IFERROR(INDEX('Người sử dụng'!$H$5:$H$140,MATCH(G10,'Người sử dụng'!$C$5:$C$140,0)),"Chưa có trong DS"))} -> Đang làm | J10: Chủ sở hữu / Admin | M10: Có | N10: Nguyễn Xuân Dũng | O10: Công ty cấp | P10: 46220 | Q10: Chạy ads | R10: Chưa bàn giao
A11: =IF(C11="","",ROW()-5) -> 6 | B11: =IF(C11="","","ADS-"&TEXT(ROW()-5,"000")) -> ADS-006 | C11: Via | D11: 100027532092068 | E11: Via | F11: https://www.facebook.com/vargas.reggie.7 | G11: NGUYỄN XUÂN DŨNG | H11: M001DUNG | I11: {=IF(G11="","",IFERROR(INDEX('Người sử dụng'!$H$5:$H$140,MATCH(G11,'Người sử dụng'!$C$5:$C$140,0)),"Chưa có trong DS"))} -> Đang làm | J11: Chủ sở hữu / Admin | M11: Có | N11: Nguyễn Xuân Dũng | O11: Công ty cấp | Q11: Chạy ads | R11: Chưa bàn giao
A12: =IF(C12="","",ROW()-5) | B12: =IF(C12="","","ADS-"&TEXT(ROW()-5,"000")) | D12: 61575801293716 | E12: Via | F12: https://www.facebook.com/profile.php?id=61575801293716 | G12: NGUYỄN XUÂN DŨNG | H12: M001DUNG | I12: {=IF(G12="","",IFERROR(INDEX('Người sử dụng'!$H$5:$H$140,MATCH(G12,'Người sử dụng'!$C$5:$C$140,0)),"Chưa có trong DS"))} -> Đang làm | J12: Chủ sở hữu / Admin | M12: Có | N12: Nguyễn Xuân Dũng | O12: Công ty cấp | P12: 46276 | Q12: Chạy ads | R12: Chưa bàn giao
A13: =IF(C13="","",ROW()-5) -> 8 | B13: =IF(C13="","","ADS-"&TEXT(ROW()-5,"000")) -> ADS-008 | C13: Page | D13: 100085100801017 | E13: page | F13: https://www.facebook.com/profile.php?id=100085100801017 | G13: NGUYỄN XUÂN DŨNG | H13: M001DUNG | I13: {=IF(G13="","",IFERROR(INDEX('Người sử dụng'!$H$5:$H$140,MATCH(G13,'Người sử dụng'!$C$5:$C$140,0)),"Chưa có trong DS"))} -> Đang làm | J13: Chủ sở hữu / Admin | O13: Công ty cấp | Q13: chạy ads | R13: Chưa bàn giao | S13: chạy ads SG
A14: =IF(C14="","",ROW()-5) -> 9 | B14: =IF(C14="","","ADS-"&TEXT(ROW()-5,"000")) -> ADS-009 | C14: Page | D14: 61550327186842 | E14: page | F14: https://www.facebook.com/profile.php?id=61550327186842 | G14: NGUYỄN XUÂN DŨNG | H14: M001DUNG | I14: {=IF(G14="","",IFERROR(INDEX('Người sử dụng'!$H$5:$H$140,MATCH(G14,'Người sử dụng'!$C$5:$C$140,0)),"Chưa có trong DS"))} -> Đang làm | J14: Chủ sở hữu / Admin | O14: Công ty cấp | Q14: chạy ads | R14: Chưa bàn giao | S14: chạy ads SG
C15: Page | D15: 111005052080409 | E15: page | F15: https://www.facebook.com/3VuTrongTien.VQY103/ | G15: NGUYỄN XUÂN DŨNG | H15: M001DUNG | I15: {=IF(G15="","",IFERROR(INDEX('Người sử dụng'!$H$5:$H$140,MATCH(G15,'Người sử dụng'!$C$5:$C$140,0)),"Chưa có trong DS"))} -> Đang làm | J15: Chủ sở hữu / Admin | O15: Công ty cấp | Q15: chạy ads | R15: Chưa bàn giao | S15: chạy ads HN
C16: Page | D16: 1967012040256785 | E16: page | F16: https://www.facebook.com/TTCB7/ | G16: NGUYỄN XUÂN DŨNG | H16: M001DUNG | I16: {=IF(G16="","",IFERROR(INDEX('Người sử dụng'!$H$5:$H$140,MATCH(G16,'Người sử dụng'!$C$5:$C$140,0)),"Chưa có trong DS"))} -> Đang làm | J16: Chủ sở hữu / Admin | O16: Công ty cấp | Q16: chạy ads | R16: Chưa bàn giao | S16: chạy ads HN
C17: Page | D17: 963061970528125 | E17: page | F17: https://www.facebook.com/DrTientantrangvungkin/ | G17: NGUYỄN XUÂN DŨNG | H17: M001DUNG | I17: {=IF(G17="","",IFERROR(INDEX('Người sử dụng'!$H$5:$H$140,MATCH(G17,'Người sử dụng'!$C$5:$C$140,0)),"Chưa có trong DS"))} -> Đang làm | J17: Chủ sở hữu / Admin | O17: Công ty cấp | Q17: chạy ads | R17: Chưa bàn giao | S17: chạy ads HN
C18: Page | D18: 102549942301147 | E18: page | F18: https://www.facebook.com/103vienquany/ | G18: NGUYỄN XUÂN DŨNG | H18: M001DUNG | I18: {=IF(G18="","",IFERROR(INDEX('Người sử dụng'!$H$5:$H$140,MATCH(G18,'Người sử dụng'!$C$5:$C$140,0)),"Chưa có trong DS"))} -> Đang làm | J18: Chủ sở hữu / Admin | O18: Công ty cấp | Q18: chạy ads | R18: Chưa bàn giao | S18: chạy ads HN
C19: Page | D19: 377662425421795 | E19: page | F19: https://www.facebook.com/profile.php?id=61561262817434 | G19: NGUYỄN XUÂN DŨNG | H19: M001DUNG | I19: {=IF(G19="","",IFERROR(INDEX('Người sử dụng'!$H$5:$H$140,MATCH(G19,'Người sử dụng'!$C$5:$C$140,0)),"Chưa có trong DS"))} -> Đang làm | J19: Chủ sở hữu / Admin | O19: Công ty cấp | Q19: chạy ads | R19: Chưa bàn giao | S19: chạy ads HN
C20: Page | D20: 887919791064480 | E20: page | F20: https://www.facebook.com/VienQuanY103VTT.02/ | G20: NGUYỄN XUÂN DŨNG | H20: M001DUNG | I20: {=IF(G20="","",IFERROR(INDEX('Người sử dụng'!$H$5:$H$140,MATCH(G20,'Người sử dụng'!$C$5:$C$140,0)),"Chưa có trong DS"))} -> Đang làm | J20: Chủ sở hữu / Admin | O20: Công ty cấp | Q20: chạy ads | R20: Chưa bàn giao | S20: chạy ads HN
C21: AI | E21: Claud | G21: NGUYỄN XUÂN DŨNG | H21: M001DUNG | I21: {=IF(G21="","",IFERROR(INDEX('Người sử dụng'!$H$5:$H$140,MATCH(G21,'Người sử dụng'!$C$5:$C$140,0)),"Chưa có trong DS"))} -> Đang làm | J21: Chủ sở hữu / Admin | K21: nqa.nguyenxuandung@gmail.com | O21: Tự tạo | R21: Chưa bàn giao
A23: =IF(C23="","",ROW()-5) -> 18 | B23: =IF(C23="","","ADS-"&TEXT(ROW()-5,"000")) -> ADS-018 | C23: Via | D23: 61577314978339 | E23: Via | F23: https://www.facebook.com/profile.php?id=61577314978339 | G23: PHƯƠNG VIỆT HOÀNG | H23: M061HOANG | I23: {=IF(G23="","",IFERROR(INDEX('Người sử dụng'!$H$5:$H$140,MATCH(G23,'Người sử dụng'!$C$5:$C$140,0)),"Chưa có trong DS"))} -> Đang làm | J23: Chủ sở hữu / Admin | M23: Có | N23: Phương Việt Hoàng | O23: Công ty cấp | Q23: Chạy ads | R23: Đã bàn giao
A24: =IF(C24="","",ROW()-5) -> 19 | B24: =IF(C24="","","ADS-"&TEXT(ROW()-5,"000")) -> ADS-019 | C24: Via | D24: 61577722010031 | E24: Via | F24: https://www.facebook.com/profile.php?id=61577722010031 | G24: PHƯƠNG VIỆT HOÀNG | H24: M061HOANG | I24: {=IF(G24="","",IFERROR(INDEX('Người sử dụng'!$H$5:$H$140,MATCH(G24,'Người sử dụng'!$C$5:$C$140,0)),"Chưa có trong DS"))} -> Đang làm | J24: Chủ sở hữu / Admin | M24: Có | N24: Phương Việt Hoàng | O24: Công ty cấp | Q24: Chạy ads | R24: Đã bàn giao
A25: =IF(C25="","",ROW()-5) -> 20 | B25: =IF(C25="","","ADS-"&TEXT(ROW()-5,"000")) -> ADS-020 | C25: Via | D25: 61577444008325 | E25: Via | F25: https://www.facebook.com/profile.php?id=61577444008325 | G25: PHƯƠNG VIỆT HOÀNG | H25: M061HOANG | I25: {=IF(G25="","",IFERROR(INDEX('Người sử dụng'!$H$5:$H$140,MATCH(G25,'Người sử dụng'!$C$5:$C$140,0)),"Chưa có trong DS"))} -> Đang làm | J25: Chủ sở hữu / Admin | M25: Có | N25: Phương Việt Hoàng | O25: Công ty cấp | Q25: Chạy ads | R25: Đã bàn giao
A26: =IF(C26="","",ROW()-5) -> 21 | B26: =IF(C26="","","ADS-"&TEXT(ROW()-5,"000")) -> ADS-021 | C26: Page | E26: Page SG | F26: https://www.facebook.com/thammytieueva.bacsivutrongtien/ | G26: PHƯƠNG VIỆT HOÀNG | H26: M061HOANG | I26: {=IF(G26="","",IFERROR(INDEX('Người sử dụng'!$H$5:$H$140,MATCH(G26,'Người sử dụng'!$C$5:$C$140,0)),"Chưa có trong DS"))} -> Đang làm | J26: Chủ sở hữu / Admin | N26: Phương Việt Hoàng | O26: Công ty cấp | Q26: chạy ads SG | R26: Đã bàn giao
A27: =IF(C27="","",ROW()-5) -> 22 | B27: =IF(C27="","","ADS-"&TEXT(ROW()-5,"000")) -> ADS-022 | C27: Page | E27: Page SG | F27: https://www.facebook.com/thammytieueva.bacsivutrongtien/ | G27: PHƯƠNG VIỆT HOÀNG | H27: M061HOANG | I27: {=IF(G27="","",IFERROR(INDEX('Người sử dụng'!$H$5:$H$140,MATCH(G27,'Người sử dụng'!$C$5:$C$140,0)),"Chưa có trong DS"))} -> Đang làm | J27: Chủ sở hữu / Admin | N27: Phương Việt Hoàng | O27: Công ty cấp | Q27: chạy ads SG | R27: Đã bàn giao
A28: =IF(C28="","",ROW()-5) -> 23 | B28: =IF(C28="","","ADS-"&TEXT(ROW()-5,"000")) -> ADS-023 | C28: VPS | D28: 103.216.118.184 | E28: Server | G28: PHƯƠNG VIỆT HOÀNG | H28: M061HOANG | I28: {=IF(G28="","",IFERROR(INDEX('Người sử dụng'!$H$5:$H$140,MATCH(G28,'Người sử dụng'!$C$5:$C$140,0)),"Chưa có trong DS"))} -> Đang làm | J28: Chủ sở hữu / Admin | N28: Phương Việt Hoàng | O28: Công ty cấp | Q28: Phòng Tài Nguyên | R28: Đã bàn giao
A29: =IF(C29="","",ROW()-5) -> 24 | B29: =IF(C29="","","ADS-"&TEXT(ROW()-5,"000")) -> ADS-024 | C29: Kênh Tiktok | E29: Kênh Tiktok HN | F29: https://www.tiktok.com/@apexmed_vutrongtien | G29: PHƯƠNG VIỆT HOÀNG | H29: M061HOANG | I29: {=IF(G29="","",IFERROR(INDEX('Người sử dụng'!$H$5:$H$140,MATCH(G29,'Người sử dụng'!$C$5:$C$140,0)),"Chưa có trong DS"))} -> Đang làm | J29: Chủ sở hữu / Admin | N29: Phương Việt Hoàng | O29: Công ty cấp | Q29: chạy ads HN | R29: Đã bàn giao
A30: =IF(C30="","",ROW()-5) -> 25 | B30: =IF(C30="","","ADS-"&TEXT(ROW()-5,"000")) -> ADS-025 | C30: TKQC Tiktok | E30: Kênh Tiktok HN | F30: https://www.tiktok.com/@bsvutrongtien29 | G30: PHƯƠNG VIỆT HOÀNG | H30: M061HOANG | I30: {=IF(G30="","",IFERROR(INDEX('Người sử dụng'!$H$5:$H$140,MATCH(G30,'Người sử dụng'!$C$5:$C$140,0)),"Chưa có trong DS"))} -> Đang làm | J30: Chủ sở hữu / Admin | N30: Phương Việt Hoàng | O30: Công ty cấp | Q30: chạy ads HN | R30: Đã bàn giao
A31: =IF(C31="","",ROW()-5) -> 26 | B31: =IF(C31="","","ADS-"&TEXT(ROW()-5,"000")) -> ADS-026 | C31: Kênh Tiktok | E31: Kênh Tiktok SG | F31: https://www.tiktok.com/@bsvutrongtienlamdep | G31: PHƯƠNG VIỆT HOÀNG | H31: M061HOANG | I31: {=IF(G31="","",IFERROR(INDEX('Người sử dụng'!$H$5:$H$140,MATCH(G31,'Người sử dụng'!$C$5:$C$140,0)),"Chưa có trong DS"))} -> Đang làm | J31: Chủ sở hữu / Admin | N31: Phương Việt Hoàng | O31: Công ty cấp | Q31: chạy ads SG | R31: Đã bàn giao
A32: =IF(C32="","",ROW()-5) -> 27 | B32: =IF(C32="","","ADS-"&TEXT(ROW()-5,"000")) -> ADS-027 | C32: Kênh Tiktok | E32: Kênh Tiktok SG | F32: https://www.tiktok.com/@drvutrongtienlamdepeva | G32: PHƯƠNG VIỆT HOÀNG | H32: M061HOANG | I32: {=IF(G32="","",IFERROR(INDEX('Người sử dụng'!$H$5:$H$140,MATCH(G32,'Người sử dụng'!$C$5:$C$140,0)),"Chưa có trong DS"))} -> Đang làm | J32: Chủ sở hữu / Admin | N32: Phương Việt Hoàng | O32: Công ty cấp | Q32: chạy ads SG | R32: Đã bàn giao
A33: =IF(C33="","",ROW()-5) -> 28 | B33: =IF(C33="","","ADS-"&TEXT(ROW()-5,"000")) -> ADS-028 | C33: Tên Miền | D33: Tenten | E33: Tenten | G33: PHƯƠNG VIỆT HOÀNG | H33: M061HOANG | I33: {=IF(G33="","",IFERROR(INDEX('Người sử dụng'!$H$5:$H$140,MATCH(G33,'Người sử dụng'!$C$5:$C$140,0)),"Chưa có trong DS"))} -> Đang làm | J33: Chủ sở hữu / Admin | N33: Phương Việt Hoàng | O33: Công ty cấp | R33: Đã bàn giao
A34: =IF(C34="","",ROW()-5) -> 29 | B34: =IF(C34="","","ADS-"&TEXT(ROW()-5,"000")) -> ADS-029 | C34: TKQC | D34: 470635541114399 | E34: TKQC FB SG | G34: PHƯƠNG VIỆT HOÀNG | H34: M061HOANG | I34: {=IF(G34="","",IFERROR(INDEX('Người sử dụng'!$H$5:$H$140,MATCH(G34,'Người sử dụng'!$C$5:$C$140,0)),"Chưa có trong DS"))} -> Đang làm | J34: Chủ sở hữu / Admin | N34: Phương Việt Hoàng | O34: Công ty cấp | Q34: chạy ads SG | R34: Đã bàn giao
A35: =IF(C35="","",ROW()-5) -> 30 | B35: =IF(C35="","","ADS-"&TEXT(ROW()-5,"000")) -> ADS-030 | C35: TKQC | D35: 3136153196597031 | E35: TKQC FB SG | G35: PHƯƠNG VIỆT HOÀNG | H35: M061HOANG | I35: {=IF(G35="","",IFERROR(INDEX('Người sử dụng'!$H$5:$H$140,MATCH(G35,'Người sử dụng'!$C$5:$C$140,0)),"Chưa có trong DS"))} -> Đang làm | J35: Chủ sở hữu / Admin | N35: Phương Việt Hoàng | O35: Công ty cấp | Q35: chạy ads SG | R35: Đã bàn giao
A36: =IF(C36="","",ROW()-5) -> 31 | B36: =IF(C36="","","ADS-"&TEXT(ROW()-5,"000")) -> ADS-031 | C36: TKQC | D36: 263888462486121 | E36: TKQC FB SG | G36: PHƯƠNG VIỆT HOÀNG | H36: M061HOANG | I36: {=IF(G36="","",IFERROR(INDEX('Người sử dụng'!$H$5:$H$140,MATCH(G36,'Người sử dụng'!$C$5:$C$140,0)),"Chưa có trong DS"))} -> Đang làm | J36: Chủ sở hữu / Admin | N36: Phương Việt Hoàng | O36: Công ty cấp | Q36: chạy ads SG | R36: Đã bàn giao
A37: =IF(C37="","",ROW()-5) -> 32 | B37: =IF(C37="","","ADS-"&TEXT(ROW()-5,"000")) -> ADS-032 | C37: TKQC | D37: 352426263050361 | E37: TKQC FB SG | G37: PHƯƠNG VIỆT HOÀNG | H37: M061HOANG | I37: {=IF(G37="","",IFERROR(INDEX('Người sử dụng'!$H$5:$H$140,MATCH(G37,'Người sử dụng'!$C$5:$C$140,0)),"Chưa có trong DS"))} -> Đang làm | J37: Chủ sở hữu / Admin | N37: Phương Việt Hoàng | O37: Công ty cấp | Q37: chạy ads SG | R37: Đã bàn giao
A38: =IF(C38="","",ROW()-5) -> 33 | B38: =IF(C38="","","ADS-"&TEXT(ROW()-5,"000")) -> ADS-033 | C38: TKQC | D38: 2534371600033681 | E38: TKQC FB SG | G38: PHƯƠNG VIỆT HOÀNG | H38: M061HOANG | I38: {=IF(G38="","",IFERROR(INDEX('Người sử dụng'!$H$5:$H$140,MATCH(G38,'Người sử dụng'!$C$5:$C$140,0)),"Chưa có trong DS"))} -> Đang làm | J38: Chủ sở hữu / Admin | N38: Phương Việt Hoàng | O38: Công ty cấp | Q38: chạy ads SG | R38: Đã bàn giao
A39: =IF(C39="","",ROW()-5) -> 34 | B39: =IF(C39="","","ADS-"&TEXT(ROW()-5,"000")) -> ADS-034 | C39: TKQC | D39: 263689352503672 | E39: TKQC FB SG | G39: PHƯƠNG VIỆT HOÀNG | H39: M061HOANG | I39: {=IF(G39="","",IFERROR(INDEX('Người sử dụng'!$H$5:$H$140,MATCH(G39,'Người sử dụng'!$C$5:$C$140,0)),"Chưa có trong DS"))} -> Đang làm | J39: Chủ sở hữu / Admin | N39: Phương Việt Hoàng | O39: Công ty cấp | Q39: chạy ads SG | R39: Đã bàn giao
A40: =IF(C40="","",ROW()-5) -> 35 | B40: =IF(C40="","","ADS-"&TEXT(ROW()-5,"000")) -> ADS-035 | C40: TKQC | D40: 384367023449993 | E40: TKQC FB SG | G40: PHƯƠNG VIỆT HOÀNG | H40: M061HOANG | I40: {=IF(G40="","",IFERROR(INDEX('Người sử dụng'!$H$5:$H$140,MATCH(G40,'Người sử dụng'!$C$5:$C$140,0)),"Chưa có trong DS"))} -> Đang làm | J40: Chủ sở hữu / Admin | N40: Phương Việt Hoàng | O40: Công ty cấp | Q40: chạy ads SG | R40: Đã bàn giao
A41: =IF(C41="","",ROW()-5) -> 36 | B41: =IF(C41="","","ADS-"&TEXT(ROW()-5,"000")) -> ADS-036 | C41: TKQC | D41: 653116649067906 | E41: TKQC FB SG | G41: PHƯƠNG VIỆT HOÀNG | H41: M061HOANG | I41: {=IF(G41="","",IFERROR(INDEX('Người sử dụng'!$H$5:$H$140,MATCH(G41,'Người sử dụng'!$C$5:$C$140,0)),"Chưa có trong DS"))} -> Đang làm | J41: Chủ sở hữu / Admin | N41: Phương Việt Hoàng | O41: Công ty cấp | Q41: chạy ads SG | R41: Đã bàn giao
...

Sheet Biên Tập
A1: KHAI BÁO TÀI NGUYÊN SỐ – BAN BIÊN TẬP
A2: Người khai báo: | E2: Ngày khai báo:
A3: Lưu ý: KHÔNG ghi mật khẩu. Ô xanh nhạt = ban điền · Cột xám = tự tính · Cột hồng = Phòng Tài nguyên điền. Người được bàn giao phải có trong tab "Người sử dụng".
A4: THÔNG TIN TÀI NGUYÊN (ban tự khai) | T4: TRẠNG THÁI THEO THÁNG (Phòng Tài nguyên cập nhật khi rà soát)
A5: STT | B5: Mã tài nguyên | C5: Loại tài nguyên | D5: ID tài nguyên | E5: Tên tài nguyên | F5: Link | G5: Người được bàn giao (đang quản lý) | H5: Mã NV | I5: Trạng thái người dùng | J5: Quyền đang có | K5: Email đăng ký | L5: SĐT đăng ký | M5: Bảo mật 2 lớp | N5: Ai đang giữ mã 2 lớp | O5: Nguồn gốc | P5: Ngày bắt đầu dùng | Q5: Mục đích sử dụng | R5: Bàn giao về Tài nguyên | S5: Ghi chú | T5: T10/2026 | U5: T11/2026 | V5: T12/2026 | W5: T01/2027 | X5: T02/2027 | Y5: T03/2027 | Z5: T04/2027 | AA5: T05/2027 | AB5: T06/2027 | AC5: T07/2027 | AD5: T08/2027 | AE5: T09/2027
A6: =IF(C6="","",ROW()-5) -> 1 | B6: =IF(C6="","","BT-"&TEXT(ROW()-5,"000")) -> BT-001 | C6: AI | H6: {=IFERROR(_xlfn.XLOOKUP(G6:G1000,'Người sử dụng'!$C$4:$C1000,'Người sử dụng'!$B$4:$B1000),"")} | I6: {=IF(G6="","",IFERROR(INDEX('Người sử dụng'!$H$5:$H$140,MATCH(G6,'Người sử dụng'!$C$5:$C$140,0)),"Chưa có trong DS"))}
A7: =IF(C7="","",ROW()-5) | B7: =IF(C7="","","BT-"&TEXT(ROW()-5,"000")) | I7: {=IF(G7="","",IFERROR(INDEX('Người sử dụng'!$H$5:$H$140,MATCH(G7,'Người sử dụng'!$C$5:$C$140,0)),"Chưa có trong DS"))}
A8: =IF(C8="","",ROW()-5) | B8: =IF(C8="","","BT-"&TEXT(ROW()-5,"000")) | I8: {=IF(G8="","",IFERROR(INDEX('Người sử dụng'!$H$5:$H$140,MATCH(G8,'Người sử dụng'!$C$5:$C$140,0)),"Chưa có trong DS"))}
A9: =IF(C9="","",ROW()-5) | B9: =IF(C9="","","BT-"&TEXT(ROW()-5,"000")) | I9: {=IF(G9="","",IFERROR(INDEX('Người sử dụng'!$H$5:$H$140,MATCH(G9,'Người sử dụng'!$C$5:$C$140,0)),"Chưa có trong DS"))}
A10: =IF(C10="","",ROW()-5) | B10: =IF(C10="","","BT-"&TEXT(ROW()-5,"000")) | I10: {=IF(G10="","",IFERROR(INDEX('Người sử dụng'!$H$5:$H$140,MATCH(G10,'Người sử dụng'!$C$5:$C$140,0)),"Chưa có trong DS"))}
A11: =IF(C11="","",ROW()-5) | B11: =IF(C11="","","BT-"&TEXT(ROW()-5,"000")) | I11: {=IF(G11="","",IFERROR(INDEX('Người sử dụng'!$H$5:$H$140,MATCH(G11,'Người sử dụng'!$C$5:$C$140,0)),"Chưa có trong DS"))}
A12: =IF(C12="","",ROW()-5) | B12: =IF(C12="","","BT-"&TEXT(ROW()-5,"000")) | I12: {=IF(G12="","",IFERROR(INDEX('Người sử dụng'!$H$5:$H$140,MATCH(G12,'Người sử dụng'!$C$5:$C$140,0)),"Chưa có trong DS"))}
A13: =IF(C13="","",ROW()-5) | B13: =IF(C13="","","BT-"&TEXT(ROW()-5,"000")) | I13: {=IF(G13="","",IFERROR(INDEX('Người sử dụng'!$H$5:$H$140,MATCH(G13,'Người sử dụng'!$C$5:$C$140,0)),"Chưa có trong DS"))}
A14: =IF(C14="","",ROW()-5) | B14: =IF(C14="","","BT-"&TEXT(ROW()-5,"000")) | I14: {=IF(G14="","",IFERROR(INDEX('Người sử dụng'!$H$5:$H$140,MATCH(G14,'Người sử dụng'!$C$5:$C$140,0)),"Chưa có trong DS"))}
A15: =IF(C15="","",ROW()-5) | B15: =IF(C15="","","BT-"&TEXT(ROW()-5,"000")) | I15: {=IF(G15="","",IFERROR(INDEX('Người sử dụng'!$H$5:$H$140,MATCH(G15,'Người sử dụng'!$C$5:$C$140,0)),"Chưa có trong DS"))}
A16: =IF(C16="","",ROW()-5) | B16: =IF(C16="","","BT-"&TEXT(ROW()-5,"000")) | I16: {=IF(G16="","",IFERROR(INDEX('Người sử dụng'!$H$5:$H$140,MATCH(G16,'Người sử dụng'!$C$5:$C$140,0)),"Chưa có trong DS"))}
A17: =IF(C17="","",ROW()-5) | B17: =IF(C17="","","BT-"&TEXT(ROW()-5,"000")) | I17: {=IF(G17="","",IFERROR(INDEX('Người sử dụng'!$H$5:$H$140,MATCH(G17,'Người sử dụng'!$C$5:$C$140,0)),"Chưa có trong DS"))}
A18: =IF(C18="","",ROW()-5) | B18: =IF(C18="","","BT-"&TEXT(ROW()-5,"000")) | I18: {=IF(G18="","",IFERROR(INDEX('Người sử dụng'!$H$5:$H$140,MATCH(G18,'Người sử dụng'!$C$5:$C$140,0)),"Chưa có trong DS"))}
... A205: =IF(C205="","",ROW()-5) | B205: =IF(C205="","","BT-"&TEXT(ROW()-5,"000")) | I205: {=IF(G205="","",IFERROR(INDEX('Người sử dụng'!$H$5:$H$140,MATCH(G205,'Người sử dụng'!$C$5:$C$140,0)),"Chưa có trong DS"))}

Sheet Thiết Kế
A1: KHAI BÁO TÀI NGUYÊN SỐ – BAN THIẾT KẾ
A2: Người khai báo: | E2: Ngày khai báo:
A3: Lưu ý: KHÔNG ghi mật khẩu. Ô xanh nhạt = ban điền · Cột xám = tự tính · Cột hồng = Phòng Tài nguyên điền. Người được bàn giao phải có trong tab "Người sử dụng".
A4: THÔNG TIN TÀI NGUYÊN (ban tự khai) | T4: TRẠNG THÁI THEO THÁNG (Phòng Tài nguyên cập nhật khi rà soát)
